Workbook

Sheet Coins
A1: Sistema Integral Financiero Tulipan - (SIFT) | N1: Version | O1: 9 - 1720
J2: =TODAY() -> 45640 | M2: =Points!I16 -> 1736 | N2: Coins
A6: Previous Production | B6: 4169.98 | C6: PRU | D6: =Points!S5 -> 32.653837 | G6: =IF(D6>=20, "¡¡Risk!!","Stable ;)") -> ¡¡Risk!! | I6: Productive Days | J6: 7 | K6: PDP | L6: =B6/J6 -> 595.71143
A8: Inicio: | B8: 45639 | C8: <-- MON | D8: modif | F8: 16 | H8: Pesos | I8: Dollars | J8: Assets | K8: Total | L8: 378963.86
A9: Final: | B9: =B8+6 -> 45645 | C9: <-- SUN | D9: form | E9: =100/B6*(F8*I10) -> 7.2902028 | F9: =B6*(E8/100)/I10 -> 0
A10: Egresos | B10: PESOS | D10: DOLLARS | F10: ASSETS | I10: 19 | J10: 0.5
A11: Day | B11: + | C11: - | D11: + | E11: - | F11: + | G11: - | H11: =Week!J14 -> 30.01 | I11: =Week!K14 -> 0.26 | J11: =4169.98*J10 -> 2084.99 | K11: =H11+(I11*I10)+J11 -> 2119.94 | M11: =I11*J22 -> 0
A12: Friday | B12: 4169.98 | C12: =30+2400+280+15+18+2+270+12+98+15+50+20+12 -> 3222 | D12: 16 | G12: 4169.98 | H12: =H11+B12-C12 -> 977.99 | I12: =I11+D12-E12 -> 16.26 | J12: =J11+((F12-G12)*J10) -> 0 | K12: =H12+(I12*I10)+J12 -> 1286.93 | L12: % | M12: =I12*J22 -> 0
A13: Saturday | C13: 79 | H13: =H12+B13-C13 -> 898.99 | I13: =I12+D13-E13 -> 16.26 | J13: =J12+((F13-G13)*J10) -> 0 | K13: =H13+(I13*I10)+J13 -> 1207.93 | L13: {=_xlfn.IFS(Points!B14<=1,10,Points!B14<=2,9,Points!B14<=3,8,Points!B14<=4,7,Points!B14<=5,6,Points!B14<=6,5,Points!B14<=7,4,Points!B14<=8,3,Points!B14<=9,2,Points!B14<=10,1)} -> 1 | M13: =I13*J22 -> 0
A14: Sunday | H14: =H13+B14-C14 -> 898.99 | I14: =I13+D14-E14 -> 16.26 | J14: =J13+((F14-G14)*J10) -> 0 | K14: =H14+(I14*I10)+J14 -> 1207.93 | L14: N | M14: =I14*J22 -> 0
A15: Monday | H15: =H14+B15-C15 -> 898.99 | I15: =I14+D15-E15 -> 16.26 | J15: =J14+((F15-G15)*J10) -> 0 | K15: =H15+(I15*I10)+J15 -> 1207.93 | L15: =L8+L18 -> 382753.5 | M15: =I15*J22 -> 0
A16: Tuesday | F16: 768 | H16: =H15+B16-C16 -> 898.99 | I16: =I15+D16-E16 -> 16.26 | J16: =J15+((F16-G16)*J10) -> 384 | K16: =H16+(I16*I10)+J16 -> 1591.93 | L16: Increment | M16: =I16*J22 -> 0
A17: Wednesday | H17: =H16+B17-C17 -> 898.99 | I17: =I16+D17-E17 -> 16.26 | J17: =J16+((F17-G17)*J10) -> 384 | K17: =H17+(I17*I10)+J17 -> 1591.93 | L17: =B9+1 -> 45646 | M17: =I17*J22 -> 0
A18: Thursday | H18: =H17+B18-C18 -> 898.99 | I18: =I17+D18-E18 -> 16.26 | J18: =J17+((F18-G18)*J10) -> 384 | K18: =H18+(I18*I10)+J18 -> 1591.93 | L18: =L8*(L13/100) -> 3789.6386 | M18: =I18*J22 -> 0
A19: Total | B19: =SUM(B12:B18) -> 4169.98 | C19: =SUM(C12:C18) -> 3301 | D19: =SUM(D12:D18) -> 16 | E19: =SUM(E12:E18) -> 0 | F19: =(F12+F13+F14+F15+F16+F17+F18)*J10 -> 384 | G19: =(G12+G13+G14+G15+G16+G17+G18)*J10 -> 2084.99 | H19: =H18 -> 898.99 | I19: =I18 -> 16.26 | J19: =J18 -> 384 | K19: =K18 -> 1591.93
B20: =B19-C19 -> 868.98 | D20: =D19-E19 -> 16 | F20: =F19-G19 -> -1700.99
A21: =IF((C19+(E19*18))>H22, "¡Presupuesto excedido!", " ") | H21: Presupuesto | V21: legada
H22: =Presupuesto!I8 -> 3945
X84: old memories
X86: Producción Anterior | Z86: 2369 | AA86: Días Productivos | AC86: 5 | AD86: PDP | AE86: =Z86/AC86 -> 473.8
X88: Inicio: | Y88: 45474 | AA88: Reserva Anterior
X89: Final: | Y89: =Y88+6 -> 45480 | AA89: 0 | AB89: 3 | AD89: 1774.5 | AE89: 1774.5
X90: Día | Y90: Ingresos | Z90: Egresos | AA90: Impuesto | AB90: Capitales B. | AC90: Puntaje | AD90: Efectivo | AE90: Tesoro Total
X91: Lunes | Y91: =((Y54*10)+(Y55*10)+(Y56*10)+(Y57*5)+(Y58*15)+(Y59*24)+(Y60*10)+Y61)-((((Z54+Z55+Z56+Z57)/5)*14)+(Z58*6.5)+(Z59*15)+(Z60*8)+(0+0+0+0)) -> 0 | Z91: =SUM(Y64:Y70) -> 0 | AA91: =(Y91*0.015)+(Z91*0.05) -> 0 | AB91: 4 | AC91: 7 | AD91: 1030.5 | AE91: =SUM(AD91) -> 1030.5
X92: Martes | Y92: =((Z54*10)+(Z55*10)+(Z56*10)+(Z57*5)+(Z58*15)+(Z59*24)+(Z60*10)+Z61)-((((AA54+AA55+AA56+AA57)/5)*14)+(AA58*6.5)+(AA59*15)+(AA60*8)+(0+0+0+0)) -> 0 | Z92: =SUM(Z64:Z70) -> 0 | AA92: =(Y92*0.015)+(Z92*0.05) -> 0 | AB92: 5 | AC92: 9 | AD92: 836.5 | AE92: =SUM(AD92) -> 836.5
X93: Miercoles | Y93: =((AA54*10)+(AA55*10)+(AA56*10)+(AA57*5)+(AA58*15)+(AA59*24)+(AA60*10)+AA61)-((((AB54+AB55+AB56+AB57)/5)*14)+(AB58*6.5)+(AB59*15)+(AB60*8)+(0+0+0+0)) -> 0 | Z93: =SUM(AA64:AA71) -> 0 | AA93: =(Y93*0.015)+(Z93*0.05) -> 0 | AE93: =SUM(AD93) -> 0
X94: Jueves | Y94: =((AB54*10)+(AB55*10)+(AB56*10)+(AB57*5)+(AB58*15)+(AB59*24)+(AB60*10)+AB61)-((((AC54+AC55+AC56+AC57)/5)*14)+(AC58*6.5)+(AC59*15)+(AC60*8)+(0+0+0+0)) -> 0 | Z94: =SUM(AB64:AB71) -> 0 | AA94: =(Y94*0.015)+(Z94*0.05) -> 0 | AE94: =SUM(AD94) -> 0
X95: Viernes | Y95: =((AC54*10)+(AC55*10)+(AC56*10)+(AC57*5)+(AC58*15)+(AC59*24)+(AC60*10)+AC61)-((((AD54+AD55+AD56+AD57)/5)*14)+(AD58*6.5)+(AD59*15)+(AD60*8)+(0+0+0+0)) -> 0 | Z95: =SUM(AC64:AC71) -> 0 | AA95: =(Y95*0.015)+(Z95*0.05) -> 0 | AE95: =SUM(AD95) -> 0
X96: Sábado | Y96: =((AD54*10)+(AD55*10)+(AD56*10)+(AD57*5)+(AD58*15)+(AD59*24)+(AD60*10)+AD61)-((((Y54+Y55+Y56+Y57)/5)*14)+(Y58*6.5)+(Y59*15)+(Y60*8)+(0+0+0+0)) -> 0 | Z96: =SUM(AD64:AD71) -> 0 | AA96: =(Y96*0.015)+(Z96*0.05) -> 0 | AE96: =SUM(AD96) -> 0
X97: Domingo | Y97: =SUM(AE54:AE61) -> 0 | Z97: =SUM(AE64:AE71) -> 0 | AA97: =(Y97*0.015)+(Z97*0.05) -> 0 | AE97: =SUM(AD97) -> 0
X98: Corte | Y98: =SUM(Y91:Y97) -> 0 | Z98: =SUM(Z91:Z97) -> 0 | AA98: =SUM(AA89,AA91:AA97) -> 0 | AB98: 5 | AC98: =AVERAGE(AC91:AC97) -> 8 | AD98: =AE89+Y98-Z98 -> 1774.5
B120: piezas | H120: 20 | K120: 40 | M120: 25 | O120: 32
H127: 7 | K127: 7 | M127: 7 | O127: 7

Sheet Week
A1: Sistema Integral Financiero Tulipan - (SIFT) | N1: Version | O1: 9 - 1720
I2: =TODAY() -> 45640 | M2: =Points!I16 -> 1736 | N2: Week
D6: Producto Semanal Unico | F6: Producto Diario Promedio
A7: Fecha Inicial | B7: Fecha Final | C7: Días Abarcados | H7: Gasto total | J7: Before
J8: ='Tabla Histórica'!M35 -> 949.47 | K8: ='Tabla Histórica'!N35 -> 0.26
A9: 45625 | B9: =A9+6 -> 45631 | C9: 6 | D9: 3424.56 | E9: 20 | F9: =D9/C9 -> 570.76 | G9: =E9/D9 -> 0.0058401663 | H9: 4200 | I9: 3 | J9: =J8+D9-H9 -> 174.03 | K9: =K8+E9-I9 -> 17.26 | L9: =J8+J9 -> 1123.5
A10: =B9+1 -> 45632 | B10: =A10+6 -> 45638 | C10: 7 | D10: 3767.48 | E10: 4 | F10: =D10/C10 -> 538.21143 | G10: =E10/D10 -> 0.0010617176 | H10: 3911.5 | I10: 21 | J10: =J9+D10-H10 -> 30.01 | K10: =K9+E10-I10 -> 0.26 | L10: =J9+J10 -> 204.04
A11: =B10+1 -> 45639 | B11: =A11+6 -> 45645 | F11: =D11/C11 -> #DIV/0! | G11: =E11/D11 -> #DIV/0! | J11: =J10+D11-H11 -> 30.01 | K11: =K10+E11-I11 -> 0.26 | L11: =J10+J11 -> 60.02
A12: =B11+1 -> 45646 | B12: =A12+6 -> 45652 | F12: =D12/C12 -> #DIV/0! | G12: =D12/C12 -> #DIV/0! | J12: =J11+D12-H12 -> 30.01 | K12: =K11+E12-I12 -> 0.26 | L12: =J11+J12 -> 60.02
A13: =B12+1 -> 45653 | B13: =A13+6 -> 45659 | F13: =D13/C13 -> #DIV/0! | G13: =E13/D13 -> #DIV/0! | J13: =J12+D13-H13 -> 30.01 | K13: =K12+E13-I13 -> 0.26 | L13: =J12+J13 -> 60.02
A14: =A9 -> 45625 | B14: =B13 -> 45659 | C14: =SUM(C9:C13) -> 13 | D14: =SUM(D9:D13) -> 7192.04 | E14: =SUM(E9:E13) -> 24 | F14: =AVERAGE(F9:F12) -> #DIV/0! | G14: =AVERAGE(G9:G12) -> #DIV/0! | H14: =SUM(H9:H13) -> 8111.5 | I14: =SUM(I9:I13) -> 24 | J14: =J8+D14-H14 -> 30.01 | K14: =K8+E14-I14 -> 0.26
D16: =Coins!B19 -> 4169.98 | E16: =Coins!D19 -> 16 | H16: =Coins!C19 -> 3301 | I16: =Coins!E19 -> 0

Sheet Presupuesto
A1: Sistema Integral Financiero Tulipan - (SIFT) | N1: Version | O1: 9 - 1720
J2: =TODAY() -> 45640 | M2: =Points!I16 -> 1736 | N2: Week
B7: Presupuesto | K7: ING ESP | M7: comida | N7: =SUM(N9:N23) -> 390
C8: Transporte | D8: Comida | E8: Extraordinario | F8: Desarrollos | G8: Pagos | H8: Suma | I8: =SUM(H9:H15) -> 3945 | J8: =Week!J14 -> 30.01 | M8: chuletas | N8: 150
B9: Friday | C9: 45 | D9: 25 | F9: 2400 | G9: 495 | H9: =SUM(C9:G9) -> 2965 | J9: =J8-H9+K9 -> 1234.99 | K9: 4169.98 | M9: huevo | N9: 120
B10: Saturday | C10: 45 | D10: 415 | G10: 225 | H10: =SUM(C10:G10) -> 685 | J10: =J9-H10+K10 -> 549.99 | M10: nopal | N10: 30
B11: Sunday | H11: =SUM(C11:G11) -> 0 | J11: =J10-H11+K11 -> 549.99 | M11: tortilla | N11: 70
B12: Monday | C12: 45 | D12: 25 | H12: =SUM(C12:G12) -> 70 | J12: =J11-H12+K12 -> 479.99 | M12: leche | N12: 80
B13: Tuesday | C13: 45 | D13: 25 | H13: =SUM(C13:G13) -> 70 | J13: =J12-H13+K13 -> 409.99 | M13: galleta | N13: 40
B14: Wednesday | C14: 45 | D14: 25 | H14: =SUM(C14:G14) -> 70 | J14: =J13-H14+K14 -> 339.99 | M14: sopa | N14: 50
B15: Thursday | C15: 60 | D15: 25 | H15: =SUM(C15:G15) -> 85 | J15: =J14-H15+K15 -> 254.99
B16: Total por ambito | C16: =SUM(C9:C15) -> 285 | D16: =SUM(D9:D15) -> 540 | E16: =SUM(E9:E15) -> 0 | F16: =SUM(F9:F15) -> 2400 | G16: =SUM(G9:G15) -> 720
I17: Presupuesto

Sheet Points
A1: Sistema Integral Financiero Tulipan - (SIFT) | L1: Version | M1: 9 - 1720
J2: =TODAY() -> 45640 | K2: =I16 -> 1736 | L2: Points
A5: History | B5: 8.6 | D5: Recurso | E5: Puntaje | F5: Risk | L5: Esp | R5: =Coins!L8/Coins!E9/Coins!K19 -> 32.653837 | S5: =R5+(R5*(F10/100))-(R5*(L10/100)) -> 32.653837
D6: Life Sources | E6: 9 | F6: Personal | G6: Academico | H6: Physic | I6: Emotional | J6: Social | K6: Finaniero | L6: Physic | M6: Emotional | N6: Social | O6: Finaniero | P6: Personal | Q6: Academico
A7: Friday | B7: 10 | D7: Recreative | E7: 9 | G7: 1 | I7: 1 | J7: 1 | K7: 1 | L7: 1 | M7: 1 | O7: 2 | P7: 1 | Q7: 1
A8: Saturday | D8: Progress | E8: 9 | G8: 30 | H8: 60 | I8: 70 | J8: 50 | K8: 100 | L8: 20 | M8: 20 | N8: 20 | O8: 60 | P8: 70 | Q8: 20
A9: Sunday | E9: =AVERAGE(E6:E8) -> 9 | F9: =F7*F8 -> 0 | G9: =G7*G8 -> 30 | H9: =H7*H8 -> 0 | I9: =I7*I8 -> 70 | J9: =J7*J8 -> 50 | K9: =K7*K8 -> 100 | L9: =L7*L8 -> 20 | M9: =M7*M8 -> 20 | ... Q9: =Q7*Q8 -> 20
A10: Monday | D10: Degenerative | E10: 7 | F10: =AVERAGE(F9:K9) -> 41.666667 | L10: =AVERAGE(L9:Q9) -> 41.666667
A11: Tuesday | E11: =AVERAGE(E9:E10) -> 8
A12: Wednesday | E12: {=_xlfn.IFS(E11<=1,10,E11<=2,9,E11<=3,8,E11<=4,7,E11<=5,6,E11<=6,5,E11<=7,4,E11<=8,3,E11<=9,2,E11<=10,1)} -> 3
A13: Thursday
B14: =AVERAGE(B7:B13) -> 10
H15: 45568
H16: 43904 | I16: =J2-H16 -> 1736 | J16: bnh | K16: =H16+I16 -> 45640 | L16: =SUM(L17:L19) -> 325799475
H17: 43011 | I17: =J2-H17 -> 2629 | J17: Mymt | K17: =H17+I17 -> 45640 | L17: 20145796
H18: 38400 | I18: =J2-H18 -> 7240 | J18: bnj | K18: =H18+I18 -> 45640 | L18: 285969752
H19: 42583 | I19: =J2-H19 -> 3057 | J19: Brrs | K19: =H19+I19 -> 45640 | L19: 19683927
H20: 38011 | I20: =J2-H20 -> 7629 | J20: Brrs | K20: =H20+I20 -> 45640

Sheet Count
A1: Sistema Integral Financiero Tulipan - (SIFT) | N1: Version | O1: 9 - 1720
I2: =TODAY() -> 45640 | M2: =Points!I16 -> 1736 | N2: Coins
A5: MXN | C5: =C6+C7 -> 299 | H5: porcentaje | I5: DOLARES | J5: EQUIVALENCIA | Q5: Retiros autorizados | S5: =SUM(Q7:Q33) -> 21
A6: MONEDA | C6: 49 | H6: 0.056 | I6: 10.26 | J6: =I6*Coins!I10 -> 194.94 | M6: Ahorro | N6: EQUIVALENCIA | Q6: MONTO | R6: EQUIVALENCIA | S6: MOTIVO
A7: BILLETE | C7: 250 | H7: 0.061 | I7: 11 | J7: =I7*Coins!I10 -> 209 | M7: =(SUM(I6:I22))-S5 -> 16.26 | N7: =M7*Coins!I10 -> 308.94 | Q7: 5 | R7: =Q7*Coins!I10 -> 95 | S7: reparaciones
A8: DÉBITOS | C8: =SUM(C9:D13) -> 599 | H8: 7.29% | I8: 16 | J8: =I8*Coins!I10 -> 304 | Q8: 1 | R8: =Q8*Coins!I10 -> 19 | S8: extra financiamiento
A9: BNM | C9: 0 | J9: =I9*Coins!I10 -> 0 | Q9: 2 | R9: =Q9*Coins!I10 -> 38 | S9: extra financiamiento
A10: EDR | C10: 350 | J10: =I10*Coins!I10 -> 0 | Q10: 7 | R10: =Q10*Coins!I10 -> 133 | S10: extra financiamiento
A11: BBV | C11: 0 | J11: =I11*Coins!I10 -> 0 | Q11: 6 | R11: =Q11*Coins!I11 -> 1.56 | S11: extra financiamiento
A12: SCT | C12: 19 | J12: =I12*Coins!I15 -> 0 | R12: =Q12*Coins!I12 -> 0
A13: SPN | C13: 230 | J13: =I13*Coins!I16 -> 0 | R13: =Q13*Coins!I13 -> 0
A14: USD | C14: =C15+C16 -> 16.26 | J14: =I14*Coins!I17 -> 0 | R14: =Q14*Coins!I14 -> 0
A15: MONEDA | C15: 0.26 | J15: =I15*Coins!I18 -> 0 | R15: =Q15*Coins!I15 -> 0
A16: BILLETE | C16: 16 | J16: =I16*Coins!I19 -> 0 | R16: =Q16*Coins!I16 -> 0
A17: Sumatoria | B17: pesos | C17: =C8+C5 -> 898 | J17: =I17*Coins!I20 -> 0 | R17: =Q17*Coins!I17 -> 0
B18: TOTAL | C18: =C17+(C14*Coins!I10) -> 1206.94 | R18: =Q18*Coins!I18 -> 0
R19: =Q19*Coins!I19 -> 0
R20: =Q20*Coins!I20 -> 0
R21: =Q21*Coins!I21 -> 0
R22: =Q22*Coins!I22 -> 0
R23: =Q23*Coins!I23 -> 0
R24: =Q24*Coins!I24 -> 0
R25: =Q25*Coins!I25 -> 0
R26: =Q26*Coins!I26 -> 0
R27: =Q27*Coins!I27 -> 0
R28: =Q28*Coins!I28 -> 0
R29: =Q29*Coins!I29 -> 0
R30: =Q30*Coins!I30 -> 0
R31: =Q31*Coins!I31 -> 0
B115: piezas
B116: nutella
B117: pan

Sheet Tabla Histórica
A1: Fecha Inicial | B1: Fecha Final | C1: Periodo | D1: Días Abarcados | E1: Proucto Mensual Total | G1: Producto Diario Promedio | I1: Gasto total | K1: Crecimiento | M1: INITIAL PESOS | N1: INITIAL DOLLARS | O1: 9 1720 version
A2: 2023C2 | D2: =SUM(D4:D7) -> 119 | E2: =SUM(E4:E7) -> 17796 | F2: =SUM(F4:F7) -> 0 | G2: =SUM(G4:G7) -> 600.02143 | H2: =SUM(H4:H7) -> 0 | I2: =SUM(I4:I7) -> 0 | J2: =SUM(J4:J7) -> 0 | K2: =SUM(K4:K7) -> 0 | L2: =SUM(L4:L7) -> 0
A4: 7 de Mayo | B4: 3 de Junio | C4: Mayo 2023 | D4: 28 | E4: 4690 | F4: NO USD | G4: =E4/D4 -> 167.5 | H4: NO USD | I4: DESC. | J4: NO USD | K4: NA | L4: NO USD
A5: 4 de Junio | B5: 1 de Julio | C5: Junio 2023 | D5: 28 | E5: 3647 | G5: =E5/D5 -> 130.25 | I5: DESC. | K5: NA
A6: 2 de Julio | B6: 29 de Julio | C6: Julio 2023 | D6: 28 | E6: 4482 | G6: =E6/D6 -> 160.07143 | I6: DESC. | K6: NA
A7: 30 de Julio | B7: 2 de Septiembre | C7: Agosto 2023 | D7: 35 | E7: 4977 | G7: =E7/D7 -> 142.2 | I7: DESC. | K7: NA
A8: 2023C3 | D8: =SUM(D10:D13) -> 119 | E8: =SUM(E10:E13) -> 31542 | F8: =SUM(F10:F13) -> 0 | G8: =SUM(G10:G13) -> 1052.5357 | H8: =SUM(H10:H13) -> 0 | I8: =SUM(I10:I13) -> 0 | J8: =SUM(J10:J13) -> 0 | K8: =SUM(K10:K13) -> 0 | L8: =SUM(L10:L13) -> 0
A10: 3 de Septiembre | B10: 30 de Septiembre | C10: Septiembre 2023 | D10: 28 | E10: 7260 | F10: NO USD | G10: =E10/D10 -> 259.28571 | H10: NO USD | I10: DESC. | J10: NO USD | K10: NA | L10: NO USD
A11: 1 de Octubre | B11: 4 de Noviembre | C11: Octubre 2023 | D11: 35 | E11: 10355 | G11: =E11/D11 -> 295.85714 | I11: DESC. | K11: NA
A12: 5 de Noviembre | B12: 3 de Diciembre | C12: Noviembre 2023 | D12: 28 | E12: 6241 | G12: =E12/D12 -> 222.89286 | I12: DESC. | K12: NA
A13: 4 de Diciembre | B13: 31 de Diciembre | C13: Diciembre 2023 | D13: 28 | E13: 7686 | G13: =E13/D13 -> 274.5 | I13: DESC. | K13: NA
A14: 7 de Mayo | B14: 31 de Diciembre | C14: 2023 | D14: =SUM(D2+D8) -> 238 | E14: =SUM(E2+E8) -> 49338 | F14: =SUM(F2+F8) -> 0 | G14: =AVERAGE(G4:G7,G10:G13) -> 206.56964 | H14: =AVERAGE(H4:H7,H1:H13) -> 0 | I14: =SUM(I2+I8) -> 0 | J14: =SUM(J2+J8) -> 0 | K14: 105 | L14: =SUM(L2+L8) -> 0 | M14: 105 | N14: =SUM(N2+N8) -> 0
A17: 2024C1 | D17: =SUM(D19:D22) -> 121 | E17: =SUM(E19:E22) -> 25635 | F17: =SUM(F19:F22) -> 0 | G17: =AVERAGE(G19:G22) -> 211.42674 | H17: =SUM(H19:H22) -> 0 | I17: =SUM(I19:I22) -> 27243 | J17: =SUM(J19:J22) -> 0 | K17: =SUM(K19:K22) -> -1608 | L17: =SUM(L19:L22) -> 0 | M17: =M14+K17 -> -1503 | N17: =N14+L17 -> 0
A19: 1 de Enero | B19: 28 de Enero | C19: Enero 2024 | D19: 28 | E19: 6371 | F19: NO USD | G19: =E19/D19 -> 227.53571 | H19: NO USD | I19: 6484 | J19: NO USD | K19: =E19-I19 -> -113 | L19: NO USD
A20: 29 de Enero | B20: 29 de Febrero | C20: Febrero 2024 | D20: 32 | E20: 7972 | G20: =E20/D20 -> 249.125 | I20: 8253 | K20: =E20-I20 -> -281
A21: 1 de Marzo | B21: 31 de Marzo | C21: Marzo 2024 | D21: 31 | E21: 6839 | G21: =E21/D21 -> 220.6129 | I21: 6553 | K21: =E21-I21 -> 286
A22: 1 de Abril | B22: 28 de Abril | C22: Abril 2024 | D22: 30 | E22: 4453 | G22: =E22/D22 -> 148.43333 | I22: 5953 | K22: =E22-I22 -> -1500
A23: 2024C2 | D23: =SUM(D25:D28) -> 107 | E23: =SUM(E25:E28) -> 27800 | F23: =SUM(F25:F28) -> 0 | G23: =AVERAGE(G25:G28) -> 259.07065 | H23: =SUM(H25:H28) -> 0 | I23: =SUM(I25:I28) -> 25434 | J23: =SUM(J25:J28) -> 0 | K23: =SUM(K25:K28) -> 2366 | L23: =SUM(L25:L28) -> 0 | M23: =M17+K23 -> 863 | N23: =N17+L23 -> 0
A25: 29 de Abril | B25: 2 de Junio | C25: Mayo 2024 | D25: 35 | E25: 7300 | F25: NO USD | G25: =E25/D25 -> 208.57143 | H25: NO USD | I25: 7711 | J25: NO USD | K25: =E25-I25 -> -411 | L25: NO USD
A26: 3 de Junio | B26: 30 de Junio | C26: Junio 2024 | D26: 23 | E26: 6136 | G26: =E26/D26 -> 266.78261 | I26: 6176.5 | K26: =E26-I26 -> -40.5
A27: 1 de Julio | B27: 28 de Julio | C27: Julio 2024 | D27: 21 | E27: 4026 | G27: =E27/D27 -> 191.71429 | I27: 1969.5 | K27: =E27-I27 -> 2056.5
A28: 29 de Julio | B28: 1 de Septiembre | C28: Agosto 2024 | D28: 28 | E28: 10338 | G28: =E28/D28 -> 369.21429 | I28: 9577 | K28: =E28-I28 -> 761
A29: 2024C3 | D29: =SUM(D31:D34) -> 63 | E29: =SUM(E31:E34) -> 23295.41 | F29: =SUM(F31:F34) -> 28.36 | G29: =AVERAGE(G31:G34) -> 280.14888 | H29: =SUM(H31:H34) -> 1.3683971 | I29: =SUM(I31:I34) -> 23208.94 | J29: =SUM(J31:J34) -> 28.1 | K29: =SUM(K31:K34) -> 86.47 | L29: =SUM(L31:L34) -> 0.26 | M29: =M23+K29 -> 949.47 | N29: =N23+L29 -> 0.26
A31: 3 de Septiembre | B31: 30 de Septiembre | C31: Septiembre 2024 | D31: 21 | E31: 4608 | F31: NO USD | G31: =E31/D31 -> 219.42857 | H31: NO USD | I31: 5018 | J31: NO USD | K31: =E31-I31 -> -410 | L31: NO USD
A32: 1 de Octubre | B32: 27 de Octubre | C32: Octubre 2024 | D32: 19 | E32: 7209 | F32: 11.05 | G32: =E32/D32 -> 379.42105 | H32: =F32/D32 -> 0.58157895 | I32: 5496.5 | J32: 0.25 | K32: =E32-I32 -> 1712.5 | L32: =F32-J32 -> 10.8
A33: 28 de ocubre | B33: 28 de Noviembre | C33: Noviembre 2024 | D33: 22 | E33: 11478.41 | F33: 17.31 | G33: =E33/D33 -> 521.74591 | H33: =F33/D33 -> 0.78681818 | I33: 12694.44 | J33: 27.85 | K33: =E33-I33 -> -1216.03 | L33: =F33-J33 -> -10.54
C34: Diciembre 2024 | D34: 1 | G34: =E34/D34 -> 0 | H34: =F34/D34 -> 0 | K34: =E34-I34 -> 0 | L34: =F34-J34 -> 0
M35: =SUM(M14+K17+K23+K29) -> 949.47 | N35: =SUM(N14+L17+L23+L29) -> 0.26
A36: 1 de Enero | B36: 31 de Diciembre | C36: 2024 | D36: =SUM(D17+D23+D29) -> 291 | E36: =SUM(E17+E23+E29) -> 76730.41 | F36: =SUM(F17+F23+F29) -> 28.36 | G36: =AVERAGE(G17,G23,G29) -> 250.21542 | H36: =SUM(H17+H23+H29) -> 1.3683971 | I36: =SUM(I17+I23+I29) -> 75885.94 | J36: =SUM(J17+J23+J29) -> 28.1 | K36: =SUM(K17+K23+K29) -> 844.47 | L36: =SUM(L17+L23+L29) -> 0.26 | M36: 0 | N36: 0
A39: 2025C1 | D39: =SUM(D41:D44) -> 4 | E39: =SUM(E41:E44) -> 0 | F39: =SUM(F41:F44) -> 0 | G39: =AVERAGE(G41:G44) -> 0 | H39: =AVERAGE(H41:H44) -> 0 | I39: =SUM(I41:I44) -> 0 | J39: =SUM(J41:J44) -> 0 | K39: =SUM(K41:K44) -> 0 | L39: =SUM(L41:L44) -> 0 | M39: =M36+K39 -> 0 | N39: =N36+L39 -> 0
C41: Enero 2025 | D41: 1 | G41: =E41/D41 -> 0 | H41: =F41/D41 -> 0 | K41: =E41-I41 -> 0 | L41: =F41-J41 -> 0
C42: Febrero 2025 | D42: 1 | G42: =E42/D42 -> 0 | H42: =F42/D42 -> 0 | K42: =E42-I42 -> 0 | L42: =F42-J42 -> 0
C43: Marzo 2025 | D43: 1 | G43: =E43/D43 -> 0 | H43: =F43/D43 -> 0 | K43: =E43-I43 -> 0 | L43: =F43-J43 -> 0
C44: Abril 2025 | D44: 1 | G44: =E44/D44 -> 0 | H44: =F44/D44 -> 0 | K44: =E44-I44 -> 0 | L44: =F44-J44 -> 0
A45: 2025C2 | D45: =SUM(D47:D50) -> 4 | E45: =SUM(E47:E50) -> 0 | F45: =SUM(F47:F50) -> 0 | G45: =AVERAGE(G47:G50) -> 0 | H45: =AVERAGE(H47:H50) -> 0 | I45: =SUM(I47:I50) -> 0 | J45: =SUM(J47:J50) -> 0 | K45: =SUM(K47:K50) -> 0 | L45: =SUM(L47:L50) -> 0 | M45: =M39+K45 -> 0 | N45: =N39+L45 -> 0
C47: Mayo 2025 | D47: 1 | G47: =E47/D47 -> 0 | H47: =F47/D47 -> 0 | K47: =E47-I47 -> 0 | L47: =F47-J47 -> 0
C48: Junio 2025 | D48: 1 | G48: =E48/D48 -> 0 | H48: =F48/D48 -> 0 | K48: =E48-I48 -> 0 | L48: =F48-J48 -> 0
C49: Julio 2025 | D49: 1 | G49: =E49/D49 -> 0 | H49: =F49/D49 -> 0 | K49: =E49-I49 -> 0 | L49: =F49-J49 -> 0
C50: Agosto 2025 | D50: 1 | G50: =E50/D50 -> 0 | H50: =F50/D50 -> 0 | K50: =E50-I50 -> 0 | L50: =F50-J50 -> 0
A51: 2025C3 | D51: =SUM(D53:D56) -> 4 | E51: =SUM(E53:E56) -> 0 | F51: =SUM(F53:F56) -> 0 | G51: =AVERAGE(G53:G56) -> 0 | H51: =AVERAGE(H53:H56) -> 0 | I51: =SUM(I53:I56) -> 0 | J51: =SUM(J53:J56) -> 0 | K51: =SUM(K53:K56) -> 0 | L51: =SUM(L53:L56) -> 0 | M51: =M45+K51 -> 0 | N51: =N45+L51 -> 0
...
