Workbook

Sheet Movil
A1: id | B1: FECHA | C1: MEDIO | D1: CUENTA | E1: CASO N | F1: CLIENTE | H1: TELEFONO | I1: ORDEN | J1: PRODUCTO | K1: ESTATUS | L1: PRECIO | M1: DESGLOSE
A2: RSTV11Mn2 | B2: 45612 | C2: Llamada | D2: 34685205 | E2: 1197915496492 | F2: ROCIO ISABEL BONIFAZ MELENDEZ | G2: 896013202935 | H2: 8675933670 / 8673190201 | I2: 1-197911727071 | J2: IZZI movil comparte tus datos 12M PROMO 3M | K2: CAN | L2: 300 | M2: =CONCATENATE("CLIENTE ", F2," ",J2, "VENDEDOR BENJAMIN SALAZAR SUPERVISOR JOSE IGNACIO QUEVEDO CASTILLO ") -> CLIENTE ROCIO ISABEL BONIFAZ MELENDEZ IZZI movil comparte tus datos 12M PROMO 3MVENDEDOR BENJAMIN SALAZAR SUPERVISOR JOSE IGNACIO QUEVEDO CASTILLO
A3: RSTV11Mn3 | B3: 45612 | C3: Llamada | D3: 13733700 | E3: 1197923613816 | F3: LUZ MARIA BAUTISTA CACERES | G3: NA | H3: 5513190756 | I3: 1-197923612873 | J3: IZZI MOVIL 5 12M | K3: ACTIVO | L3: 120 | M3: =CONCATENATE("CLIENTE ", F3," ",J3, "VENDEDOR BENJAMIN SALAZAR SUPERVISOR JOSE IGNACIO QUEVEDO CASTILLO ") -> CLIENTE LUZ MARIA BAUTISTA CACERES IZZI MOVIL 5 12MVENDEDOR BENJAMIN SALAZAR SUPERVISOR JOSE IGNACIO QUEVEDO CASTILLO
A4: RSTV11Mn5 | B4: 45614 | C4: Llamada | D4: 31447377 | E4: 1198048264387 | F4: MARCOS DAVID PASTRANA AVILES | G4: PSAVMR80041109H200 | H4: 5624211643 | I4: 1-198047695232 | J4: IZZI movil comparte tus datos 12M PROMO 3M | K4: ACTIVO | L4: 300 | M4: =CONCATENATE("CLIENTE ", F4," ",J4, "VENDEDOR BENJAMIN SALAZAR SUPERVISOR JOSE IGNACIO QUEVEDO CASTILLO ") -> CLIENTE MARCOS DAVID PASTRANA AVILES IZZI movil comparte tus datos 12M PROMO 3MVENDEDOR BENJAMIN SALAZAR SUPERVISOR JOSE IGNACIO QUEVEDO CASTILLO
A5: RSTV11Mn6 | B5: 45615 | C5: Calixta | D5: 37958415 | E5: 1198190397773 | F5: ITZEL MERARI GONZÁLEZ RODRÍGUEZ | G5: GNRDIT93112509M000 | H5: 5564519886 | I5: 1-198190397024 | J5: IZZI movil comparte tus datos 12M PROMO 3M | K5: ACTIVO | L5: 300 | M5: =CONCATENATE("CLIENTE ", F5," ",J5, "VENDEDOR BENJAMIN SALAZAR SUPERVISOR JOSE IGNACIO QUEVEDO CASTILLO ") -> CLIENTE ITZEL MERARI GONZÁLEZ RODRÍGUEZ IZZI movil comparte tus datos 12M PROMO 3MVENDEDOR BENJAMIN SALAZAR SUPERVISOR JOSE IGNACIO QUEVEDO CASTILLO
A6: RSTV11Mn7 | B6: 45615 | C6: Llamada | D6: 27059311 | E6: 1198206232679 | F6: ITZEL DEL CARMEN CARDENAS REYES | G6: CRRYIT88111309M200 | H6: 4425855416 | I6: 1-198184801938 | J6: IZZI movil comparte tus datos 12M PROMO 3M | K6: ACTIVO | L6: 300 | M6: =CONCATENATE("CLIENTE ", F6," ",J6, "VENDEDOR BENJAMIN SALAZAR SUPERVISOR JOSE IGNACIO QUEVEDO CASTILLO ") -> CLIENTE ITZEL DEL CARMEN CARDENAS REYES IZZI movil comparte tus datos 12M PROMO 3MVENDEDOR BENJAMIN SALAZAR SUPERVISOR JOSE IGNACIO QUEVEDO CASTILLO
A7: RSTV11Mn8 | B7: 45616 | C7: Calixta | D7: 37183202 | E7: 1198286436283 | F7: MARIANA INES CERVANTES VELAZQUEZ | G7: CRVLMR87012115M900 | H7: 5645565692 | I7: 1-198294587328 | J7: IZZI movil comparte tus datos 12M PROMO 3M | K7: CAN | L7: 300 | M7: =CONCATENATE("CLIENTE ", F7," ",J7, "VENDEDOR BENJAMIN SALAZAR SUPERVISOR JOSE IGNACIO QUEVEDO CASTILLO ") -> CLIENTE MARIANA INES CERVANTES VELAZQUEZ IZZI movil comparte tus datos 12M PROMO 3MVENDEDOR BENJAMIN SALAZAR SUPERVISOR JOSE IGNACIO QUEVEDO CASTILLO
A8: RSTV11Mn9 | B8: 45616 | C8: Calixta | D8: 39820561 | E8: 1198286435967 | F8: ANA MARIA RENTERIA ALVAREZ | G8: RNAVMR980814M600 | H8: 5511510247 | I8: 1-198286435449 | J8: IZZI movil comparte tus datos 12M PROMO 3M | K8: ACTIVO | L8: 300 | M8: =CONCATENATE("CLIENTE ", F8," ",J8, "VENDEDOR BENJAMIN SALAZAR SUPERVISOR JOSE IGNACIO QUEVEDO CASTILLO ") -> CLIENTE ANA MARIA RENTERIA ALVAREZ IZZI movil comparte tus datos 12M PROMO 3MVENDEDOR BENJAMIN SALAZAR SUPERVISOR JOSE IGNACIO QUEVEDO CASTILLO
A9: RSTV11Mn10 | B9: 45617 | C9: Llamada | D9: 42395388 | E9: 1198357319353 | F9: CLAUDIA CUAUTLE TORRES | G9: CTTRCL72041821M700 | H9: 2226614662 2225030441 | I9: 1-198357318524 | J9: IZZI movil comparte tus datos 12M PROMO 3M | K9: PRE-ACT | L9: 300 | M9: =CONCATENATE("CLIENTE ", F9," ",J9, "VENDEDOR BENJAMIN SALAZAR SUPERVISOR JOSE IGNACIO QUEVEDO CASTILLO ") -> CLIENTE CLAUDIA CUAUTLE TORRES IZZI movil comparte tus datos 12M PROMO 3MVENDEDOR BENJAMIN SALAZAR SUPERVISOR JOSE IGNACIO QUEVEDO CASTILLO
A10: RSTV11Mn11 | B10: 45617 | C10: Calixta | D10: 42759289 | E10: 1198461277913 | F10: CARLOS GUIJARRO ROJAS | G10: GJRJCR82090809H000 | H10: 4421684966 | I10: 1-198461277389 | J10: IZZI movil comparte tus datos 12M PROMO 3M | K10: PRE-ACT | L10: 300 | M10: =CONCATENATE("CLIENTE ", F10," ",J10, "VENDEDOR BENJAMIN SALAZAR SUPERVISOR IGNACIO QUEVEDO CASTILLO ") -> CLIENTE CARLOS GUIJARRO ROJAS IZZI movil comparte tus datos 12M PROMO 3MVENDEDOR BENJAMIN SALAZAR SUPERVISOR IGNACIO QUEVEDO CASTILLO
A11: RSTV11Mn12 | B11: 45617 | C11: Calixta | D11: 37288382 | F11: ALVARO MARTINEZ TORRES | G11: NA | H11: 7227868723 | J11: IZZI movil comparte tus datos 12M PROMO 3M | K11: PRE-ACT | L11: 150 | M11: =CONCATENATE("CLIENTE ", F11," ",J11, "VENDEDOR BENJAMIN SALAZAR SUPERVISOR JOSE IGNACIO QUEVEDO CASTILLO ") -> CLIENTE ALVARO MARTINEZ TORRES IZZI movil comparte tus datos 12M PROMO 3MVENDEDOR BENJAMIN SALAZAR SUPERVISOR JOSE IGNACIO QUEVEDO CASTILLO
A12: RSTV11Mn13 | B12: 45621 | C12: Calixta | D12: 34708928 | E12: 1198726087153 | F12: CLARA AMPARAN ELISERIO | G12: AMELCL88072810M000 | H12: 8125132134 | I12: 1-198726086385 | J12: IZZI movil comparte tus datos 12M PROMO 3M | K12: PRE-ACT | L12: 300 | M12: =CONCATENATE("CLIENTE ", F12," ",J12, "VENDEDOR BENJAMIN SALAZAR SUPERVISOR JOSE IGNACIO QUEVEDO CASTILLO ") -> CLIENTE CLARA AMPARAN ELISERIO IZZI movil comparte tus datos 12M PROMO 3MVENDEDOR BENJAMIN SALAZAR SUPERVISOR JOSE IGNACIO QUEVEDO CASTILLO
A13: RSTV11Mn14 | B13: 45621 | C13: Calixta | D13: 34708928 | E13: 1198726087153 | F13: CLARA AMPARAN ELISERIO | G13: AMELCL88072810M000 | H13: 8125132134 | I13: 1-198726086385 | J13: IZZI movil comparte tus datos 12M PROMO 3M | K13: PRE-ACT | L13: 300 | M13: =CONCATENATE("CLIENTE ", F13," ",J13, "VENDEDOR BENJAMIN SALAZAR SUPERVISOR JOSE IGNACIO QUEVEDO CASTILLO ") -> CLIENTE CLARA AMPARAN ELISERIO IZZI movil comparte tus datos 12M PROMO 3MVENDEDOR BENJAMIN SALAZAR SUPERVISOR JOSE IGNACIO QUEVEDO CASTILLO
A14: RSTV11Mn15 | B14: 45623 | C14: Calixta | D14: 35642246 | E14: 1198908812316 | F14: MANLIO MANUEL BAUTISTA MERCHANT | G14: BTMRMN79092709H700 | H14: 5569305132 | I14: 1-198908811622 | J14: IZZI movil comparte tus datos 12M PROMO 3M | K14: CAN | L14: 300 | M14: =CONCATENATE("CLIENTE ", F14," ",J14, "VENDEDOR BENJAMIN SALAZAR SUPERVISOR JOSE IGNACIO QUEVEDO CASTILLO ") -> CLIENTE MANLIO MANUEL BAUTISTA MERCHANT IZZI movil comparte tus datos 12M PROMO 3MVENDEDOR BENJAMIN SALAZAR SUPERVISOR JOSE IGNACIO QUEVEDO CASTILLO
A15: RSTV11Mn16 | B15: 45624 | C15: Calixta | D15: 42982360 | E15: 1199015620251 | F15: MARLA ROSARIO ALONSO MARTINEZ | G15: ALMRMR97100720M900 | H15: 9514539051 | I15: 1-199015619546 | J15: IZZI MOVIL 5 12M | K15: PRE-ACT | L15: 120 | M15: =CONCATENATE("CLIENTE ", F15," ",J15, "VENDEDOR BENJAMIN SALAZAR SUPERVISOR JOSE IGNACIO QUEVEDO CASTILLO ") -> CLIENTE MARLA ROSARIO ALONSO MARTINEZ IZZI MOVIL 5 12MVENDEDOR BENJAMIN SALAZAR SUPERVISOR JOSE IGNACIO QUEVEDO CASTILLO
A16: RSTV11Mn17 | B16: 45624 | C16: Llamada | D16: 31105859 | E16: 1199030594441 | F16: CARLOS PEREYRA QUINTERO | G16: PRQNCR86020719H700 | H16: 8118276980 | I16: 1-199030593745 | J16: IZZI MOVIL 5 12M | K16: CAN | L16: 120 | M16: =CONCATENATE("CLIENTE ", F16," ",J16, "VENDEDOR BENJAMIN SALAZAR SUPERVISOR JOSE IGNACIO QUEVEDO CASTILLO ") -> CLIENTE CARLOS PEREYRA QUINTERO IZZI MOVIL 5 12MVENDEDOR BENJAMIN SALAZAR SUPERVISOR JOSE IGNACIO QUEVEDO CASTILLO
A17: RSTV11Mn18 | B17: 45624 | C17: Llamada | D17: 31105859 | E17: 1199030594441 | F17: CARLOS PEREYRA QUINTERO | G17: PRQNCR86020719H700 | H17: 8118276980 | I17: 1-199030593745 | J17: IZZI MOVIL 5 12M | K17: CAN | L17: 120 | M17: =CONCATENATE("CLIENTE ", F17," ",J17, "VENDEDOR BENJAMIN SALAZAR SUPERVISOR JOSE IGNACIO QUEVEDO CASTILLO ") -> CLIENTE CARLOS PEREYRA QUINTERO IZZI MOVIL 5 12MVENDEDOR BENJAMIN SALAZAR SUPERVISOR JOSE IGNACIO QUEVEDO CASTILLO
A18: RSTV11Mn19 | B18: 45624 | C18: Calixta | D18: 36757559 | E18: 1199045177655 | F18: ANA LILIA MARTINEZ VAZQUEZ | G18: MRVZAN84050215M700 | H18: 5568898077 | I18: 1-199020380305 | J18: IZZI MOVIL 5 12M | K18: ACTIVO | L18: 120 | M18: =CONCATENATE("CLIENTE ", F18," ",J18, "VENDEDOR BENJAMIN SALAZAR SUPERVISOR JOSE IGNACIO QUEVEDO CASTILLO ") -> CLIENTE ANA LILIA MARTINEZ VAZQUEZ IZZI MOVIL 5 12MVENDEDOR BENJAMIN SALAZAR SUPERVISOR JOSE IGNACIO QUEVEDO CASTILLO
A19: RSTV11Mn20 | B19: 45624 | C19: Llamada | D19: 39544763 | E19: 1199045177639 | F19: ISAI OROZCO PEÑA | G19: ORPEIS92032114H000 | H19: 3328323762 | I19: 1-199045177031 | J19: IZZI movil comparte tus datos 12M PROMO 3M | K19: PRE-ACT | L19: 300 | M19: =CONCATENATE("CLIENTE ", F19," ",J19, "VENDEDOR BENJAMIN SALAZAR SUPERVISOR JOSE IGNACIO QUEVEDO CASTILLO ") -> CLIENTE ISAI OROZCO PEÑA IZZI movil comparte tus datos 12M PROMO 3MVENDEDOR BENJAMIN SALAZAR SUPERVISOR JOSE IGNACIO QUEVEDO CASTILLO
A20: RSTV11Mn21 | B20: 45625 | C20: Calixta | D20: 41366077 | E20: 1199101267462 | F20: VANIA FABIOLA ALVAREZ AGUILAR | G20: ALAGVN90103015M000 | H20: 7227753535 | I20: 1-199092215288 | J20: IZZI movil comparte tus datos 12M PROMO 3M | K20: PRE-ACT | L20: 300 | M20: =CONCATENATE("CLIENTE ", F20," ",J20, "VENDEDOR BENJAMIN SALAZAR SUPERVISOR JOSE IGNACIO QUEVEDO CASTILLO ") -> CLIENTE VANIA FABIOLA ALVAREZ AGUILAR IZZI movil comparte tus datos 12M PROMO 3MVENDEDOR BENJAMIN SALAZAR SUPERVISOR JOSE IGNACIO QUEVEDO CASTILLO
A21: RSTV11Mn24 | B21: 45625 | C21: Calixta | D21: 41366077 | E21: 1199115815858 | F21: VANIA FABIOLA ALVAREZ AGUILAR | G21: ALAGVN90103015M000 | H21: 7227753535 | I21: 1-199115813667 | J21: IZZI movil comparte tus datos 12M PROMO 3M | K21: PRE-ACT | L21: 300 | M21: =CONCATENATE("CLIENTE ", F21," ",J21, "VENDEDOR BENJAMIN SALAZAR SUPERVISOR JOSE IGNACIO QUEVEDO CASTILLO ") -> CLIENTE VANIA FABIOLA ALVAREZ AGUILAR IZZI movil comparte tus datos 12M PROMO 3MVENDEDOR BENJAMIN SALAZAR SUPERVISOR JOSE IGNACIO QUEVEDO CASTILLO
A22: RSTV11Mn25 | B22: 45625 | C22: Calixta | D22: 41366077 | E22: 1199115815858 | F22: VANIA FABIOLA ALVAREZ AGUILAR | G22: ALAGVN90103015M000 | H22: 7227753535 | I22: 1-199115815280 | J22: IZZI movil comparte tus datos 12M PROMO 3M | K22: PRE-ACT | L22: 300 | M22: =CONCATENATE("CLIENTE ", F22," ",J22, "VENDEDOR BENJAMIN SALAZAR SUPERVISOR JOSE IGNACIO QUEVEDO CASTILLO ") -> CLIENTE VANIA FABIOLA ALVAREZ AGUILAR IZZI movil comparte tus datos 12M PROMO 3MVENDEDOR BENJAMIN SALAZAR SUPERVISOR JOSE IGNACIO QUEVEDO CASTILLO
A23: RSTV11Mn26 | B23: 45625 | C23: Calixta | D23: 43445700 | E23: 1199115816458 | F23: ADOLFO ALEJANDRO SEGUNDO MELCHOR | G23: SGMLAD91121819H400 | H23: 8124217373 | I23: 1-199115815923 | J23: IZZI MOVIL 5 12M | K23: ACTIVO | L23: 120 | M23: =CONCATENATE("CLIENTE ", F23," ",J23, "VENDEDOR BENJAMIN SALAZAR SUPERVISOR JOSE IGNACIO QUEVEDO CASTILLO ") -> CLIENTE ADOLFO ALEJANDRO SEGUNDO MELCHOR IZZI MOVIL 5 12MVENDEDOR BENJAMIN SALAZAR SUPERVISOR JOSE IGNACIO QUEVEDO CASTILLO
A24: RSTV11Mn26 | B24: 45625 | C24: Calixta | D24: 38796180 | E24: 1199126065432 | F24: CARLOS HERNANDEZ HERNANDEZ | G24: HRHRCR86071224H900 | H24: 3330068912 | I24: 1-199115816486 | J24: IZZI MOVIL 5 12M | K24: PRE-ACT | L24: 120 | M24: =CONCATENATE("CLIENTE ", F24," ",J24, "VENDEDOR BENJAMIN SALAZAR SUPERVISOR JOSE IGNACIO QUEVEDO CASTILLO ") -> CLIENTE CARLOS HERNANDEZ HERNANDEZ IZZI MOVIL 5 12MVENDEDOR BENJAMIN SALAZAR SUPERVISOR JOSE IGNACIO QUEVEDO CASTILLO
A25: RSTV11Mn27 | B25: 45625 | C25: Calixta | D25: 38796180 | E25: 1199126065432 | F25: CARLOS HERNANDEZ HERNANDEZ | G25: HRHRCR86071224H900 | H25: 3330068912 | I25: 1-199115816486 | J25: IZZI MOVIL 5 12M | K25: PRE-ACT | L25: 120 | M25: =CONCATENATE("CLIENTE ", F25," ",J25, "VENDEDOR BENJAMIN SALAZAR SUPERVISOR JOSE IGNACIO QUEVEDO CASTILLO ") -> CLIENTE CARLOS HERNANDEZ HERNANDEZ IZZI MOVIL 5 12MVENDEDOR BENJAMIN SALAZAR SUPERVISOR JOSE IGNACIO QUEVEDO CASTILLO
A26: RSTV11Mn28 | B26: 45625 | C26: Calixta | D26: 38796180 | E26: 1199126065432 | F26: CARLOS HERNANDEZ HERNANDEZ | G26: HRHRCR86071224H900 | H26: 3330068912 | I26: 1-199115816486 | J26: IZZI MOVIL 5 12M | K26: PRE-ACT | L26: 120 | M26: =CONCATENATE("CLIENTE ", F26," ",J26, "VENDEDOR BENJAMIN SALAZAR SUPERVISOR JOSE IGNACIO QUEVEDO CASTILLO ") -> CLIENTE CARLOS HERNANDEZ HERNANDEZ IZZI MOVIL 5 12MVENDEDOR BENJAMIN SALAZAR SUPERVISOR JOSE IGNACIO QUEVEDO CASTILLO
A27: RSTV11Mn30 | B27: 45626 | C27: Calixta | D27: 36560305 | E27: 1199168306097 | F27: RELOCATION SOLUTION WORLDWIDE | G27: BNRZSF84090287M900 | H27: 6441370246 | I27: 1-199162970761 | J27: IZZI MOVIL 8 | K27: ACTIVO | L27: 180 | M27: =CONCATENATE("CLIENTE ", F27," ",J27, "VENDEDOR BENJAMIN SALAZAR SUPERVISOR JOSE IGNACIO QUEVEDO CASTILLO ") -> CLIENTE RELOCATION SOLUTION WORLDWIDE IZZI MOVIL 8VENDEDOR BENJAMIN SALAZAR SUPERVISOR JOSE IGNACIO QUEVEDO CASTILLO
A28: RSTV11Mn31 | B28: 45626 | C28: Calixta | D28: 36560305 | E28: 1199168306097 | F28: RELOCATION SOLUTION WORLDWIDE | G28: BNRZSF84090287M900 | H28: 6441370246 | I28: 1-199162970761 | J28: IZZI MOVIL 8 | K28: ACTIVO | L28: 180 | M28: =CONCATENATE("CLIENTE ", F28," ",J28, "VENDEDOR BENJAMIN SALAZAR SUPERVISOR JOSE IGNACIO QUEVEDO CASTILLO ") -> CLIENTE RELOCATION SOLUTION WORLDWIDE IZZI MOVIL 8VENDEDOR BENJAMIN SALAZAR SUPERVISOR JOSE IGNACIO QUEVEDO CASTILLO
A29: RSTV11Mn32 | B29: 45626 | C29: Calixta | D29: 39262845 | E29: 1199186568906 | F29: ADRIANA MARIBEL LOPEZ CORONA | G29: LPCRAD95051518M200 | H29: 3113162509 | I29: 1-199176504220 | J29: IZZI MOVIL 8 | K29: ACTIVO | L29: 180 | M29: =CONCATENATE("CLIENTE ", F29," ",J29, "VENDEDOR BENJAMIN SALAZAR SUPERVISOR JOSE IGNACIO QUEVEDO CASTILLO ") -> CLIENTE ADRIANA MARIBEL LOPEZ CORONA IZZI MOVIL 8VENDEDOR BENJAMIN SALAZAR SUPERVISOR JOSE IGNACIO QUEVEDO CASTILLO
A30: RSTV11Mn33 | B30: 45626 | C30: Llamada | D30: 42054272 | E30: 1199186570190 | F30: LILIANA YANETTE VELEZ SANCHEZ | G30: VLSNLL77112919M001 | H30: 8181639458 | I30: 1-199186569559 | J30: IZZI movil comparte tus datos 12M PROMO 3M | K30: ACTIVO | L30: 300 | M30: =CONCATENATE("CLIENTE ", F30," ",J30, "VENDEDOR BENJAMIN SALAZAR SUPERVISOR JOSE IGNACIO QUEVEDO CASTILLO ") -> CLIENTE LILIANA YANETTE VELEZ SANCHEZ IZZI movil comparte tus datos 12M PROMO 3MVENDEDOR BENJAMIN SALAZAR SUPERVISOR JOSE IGNACIO QUEVEDO CASTILLO
A31: RSTV11Mn34 | B31: 45628 | C31: llamada | D31: 35062679 | E31: 1199323754136 | F31: ADRIANA LETICIA HUERTA ALVARADO | G31: HRALAD76082709M500 | H31: 5567913181 | I31: 1-199335892885 | J31: IZZI movil comparte tus datos 12M PROMO 3M | K31: PRE-ACT | L31: 300 | M31: =CONCATENATE("CLIENTE ", F31," ",J31, "VENDEDOR BENJAMIN SALAZAR SUPERVISOR JOSE IGNACIO QUEVEDO CASTILLO ") -> CLIENTE ADRIANA LETICIA HUERTA ALVARADO IZZI movil comparte tus datos 12M PROMO 3MVENDEDOR BENJAMIN SALAZAR SUPERVISOR JOSE IGNACIO QUEVEDO CASTILLO
A32: RSTV11Mn35 | B32: 45628 | C32: llamada | D32: 35062679 | E32: 1199323754136 | F32: ADRIANA LETICIA HUERTA ALVARADO | G32: HRALAD76082709M500 | H32: 5567913181 | I32: 1-199335892885 | J32: IZZI movil comparte tus datos 12M PROMO 3M | K32: PRE-ACT | L32: 300 | M32: =CONCATENATE("CLIENTE ", F32," ",J32, "VENDEDOR BENJAMIN SALAZAR SUPERVISOR JOSE IGNACIO QUEVEDO CASTILLO ") -> CLIENTE ADRIANA LETICIA HUERTA ALVARADO IZZI movil comparte tus datos 12M PROMO 3MVENDEDOR BENJAMIN SALAZAR SUPERVISOR JOSE IGNACIO QUEVEDO CASTILLO
A33: RSTV11Mn36 | B33: 45629 | C33: llamada | D33: 17581194 | E33: 1199404862191 | F33: PABLO . GONZALEZ BAUTISTA | G33: GNBTPB50123115H700 | H33: 5532318571 | I33: 1-199354744393 | J33: IZZI MOVIL 5 12M | K33: PRE-ACT | L33: 120 | M33: =CONCATENATE("CLIENTE ", F33," ",J33, "VENDEDOR BENJAMIN SALAZAR SUPERVISOR JOSE IGNACIO QUEVEDO CASTILLO ") -> CLIENTE PABLO . GONZALEZ BAUTISTA IZZI MOVIL 5 12MVENDEDOR BENJAMIN SALAZAR SUPERVISOR JOSE IGNACIO QUEVEDO CASTILLO
A34: RSTV11Mn37 | B34: 45630 | C34: llamada | D34: 34245050 | E34: 1199498376882 | F34: ANA VALERIA LOPEZ PEREZ | G34: LPPRAN93012915M500 | H34: 5533327491 | I34: 1-199492628708 | J34: IZZI MOVIL 8 12M | K34: PRE-ACT | L34: 150 | M34: =CONCATENATE("CLIENTE ", F34," ",J34, "VENDEDOR BENJAMIN SALAZAR SUPERVISOR JOSE IGNACIO QUEVEDO CASTILLO ") -> CLIENTE ANA VALERIA LOPEZ PEREZ IZZI MOVIL 8 12MVENDEDOR BENJAMIN SALAZAR SUPERVISOR JOSE IGNACIO QUEVEDO CASTILLO
A35: RSTV11Mn38 | B35: 45630 | C35: llamada | D35: 34245050 | E35: 1199498376882 | F35: ANA VALERIA LOPEZ PEREZ | G35: LPPRAN93012915M500 | H35: 5533327491 | I35: 1-199492628708 | J35: IZZI MOVIL 8 12M | K35: PRE-ACT | L35: 150 | M35: =CONCATENATE("CLIENTE ", F35," ",J35, "VENDEDOR BENJAMIN SALAZAR SUPERVISOR JOSE IGNACIO QUEVEDO CASTILLO ") -> CLIENTE ANA VALERIA LOPEZ PEREZ IZZI MOVIL 8 12MVENDEDOR BENJAMIN SALAZAR SUPERVISOR JOSE IGNACIO QUEVEDO CASTILLO
A36: RSTV11Mn40 | B36: 45631 | C36: llamada | D36: 43616250 | E36: 1199540191446 | F36: JUVENCIO CRUZ CASTAÑEDA | G36: CRCSJV73082821H600 | H36: 5539193430 | I36: 1-199577337742 | J36: IZZI MOVIL 8 12M | K36: PRE-ACT | L36: 300 | M36: =CONCATENATE("CLIENTE ", F36," ",J36, "VENDEDOR BENJAMIN SALAZAR SUPERVISOR JOSE IGNACIO QUEVEDO CASTILLO ") -> CLIENTE JUVENCIO CRUZ CASTAÑEDA IZZI MOVIL 8 12MVENDEDOR BENJAMIN SALAZAR SUPERVISOR JOSE IGNACIO QUEVEDO CASTILLO
A37: RSTV11Mn44 | B37: 45632 | C37: llamada | D37: 43097203 | E37: 1199659184972 | F37: JUAN ANTONIO SALAZAR JASSO | G37: SLJSJN95061319H400 | H37: 8110292026 | I37: 1-199664108628 | J37: IZZI MOVIL 8 12M | K37: PRE-ACT | L37: 150 | M37: =CONCATENATE("CLIENTE ", F37," ",J37, "VENDEDOR BENJAMIN SALAZAR SUPERVISOR JOSE IGNACIO QUEVEDO CASTILLO ") -> CLIENTE JUAN ANTONIO SALAZAR JASSO IZZI MOVIL 8 12MVENDEDOR BENJAMIN SALAZAR SUPERVISOR JOSE IGNACIO QUEVEDO CASTILLO
A38: RSTV11Mn48 | B38: 45632 | C38: Calixta | D38: 37743747 | E38: 1199686862132 | F38: ALEJANDRA SARAHI TAPIA ESPINOSA | G38: TPESAL93070219M600 | H38: 8129450591 | I38: 1-199688191372 | J38: IZZI MOVIL 5 12M | K38: PRE-ACT | L38: 120 | M38: =CONCATENATE("CLIENTE ", F38," ",J38, "VENDEDOR BENJAMIN SALAZAR SUPERVISOR JOSE IGNACIO QUEVEDO CASTILLO ") -> CLIENTE ALEJANDRA SARAHI TAPIA ESPINOSA IZZI MOVIL 5 12MVENDEDOR BENJAMIN SALAZAR SUPERVISOR JOSE IGNACIO QUEVEDO CASTILLO
A39: RSTV11Mn52 | B39: 45633 | C39: Llamada | D39: 36410582 | E39: 1199783997392 | F39: EMANUEL LOBATO RUIZ | G39: LBRZEM01100915H700 | H39: 5625868953 | I39: 1-199767113608 | J39: IZZI movil comparte tus datos 12M PROMO 3M | K39: PRE-ACT | L39: 300 | M39: =CONCATENATE("CLIENTE ", F39," ",J39, "VENDEDOR BENJAMIN SALAZAR SUPERVISOR JOSE IGNACIO QUEVEDO CASTILLO ") -> CLIENTE EMANUEL LOBATO RUIZ IZZI movil comparte tus datos 12M PROMO 3MVENDEDOR BENJAMIN SALAZAR SUPERVISOR JOSE IGNACIO QUEVEDO CASTILLO
A40: RSTV11Mn53 | B40: 45633 | C40: Llamada | D40: 36410582 | E40: 1199783997392 | F40: EMANUEL LOBATO RUIZ | G40: LBRZEM01100915H700 | H40: 5625868953 | I40: 1-199767113608 | J40: IZZI movil comparte tus datos 12M PROMO 3M | K40: PRE-ACT | L40: 300 | M40: =CONCATENATE("CLIENTE ", F40," ",J40, "VENDEDOR BENJAMIN SALAZAR SUPERVISOR JOSE IGNACIO QUEVEDO CASTILLO ") -> CLIENTE EMANUEL LOBATO RUIZ IZZI movil comparte tus datos 12M PROMO 3MVENDEDOR BENJAMIN SALAZAR SUPERVISOR JOSE IGNACIO QUEVEDO CASTILLO
...

Sheet UPs
A1: id | B1: FECHA | C1: MEDIO | D1: CUENTA | E1: CASO N | F1: CLIENTE | H1: TELEFONO | I1: ORDEN | J1: PRODUCTO | K1: ESTATUS | L1: PRECIO | M1: DESGLOSE
A2: RSTV11Mn1 | B2: 45612 | C2: Llamada | D2: 21263814 | E2: 1197911726237 | F2: JOSE LUIS GONZALEZ ANCIRA | G2: NA | H2: 8115165656 | I2: 1-197911725730 | J2: disney $219 | K2: ACTIVO | L2: UPSALE | M2: =CONCATENATE("CLIENTE ", F2," ",J2, "VENDEDOR BENJAMIN SALAZAR SUPERVISOR JOSE IGNACIO QUEVEDO CASTILLO ") -> CLIENTE JOSE LUIS GONZALEZ ANCIRA disney $219 VENDEDOR BENJAMIN SALAZAR SUPERVISOR JOSE IGNACIO QUEVEDO CASTILLO
A3: RSTV11Mn4 | B3: 45614 | C3: Llamada | D3: 43344252 | E3: 1198047695213 | F3: JUAN CARLOS QUIROZ TORRES | G3: QRTRJN89082715H300 | H3: 7299069234 | I3: 1-198047694745 | J3: NETFLIX 4S | K3: ACTIVO | L3: UPSALE | M3: =CONCATENATE("CLIENTE ", F3," ",J3, "VENDEDOR BENJAMIN SALAZAR SUPERVISOR JOSE IGNACIO QUEVEDO CASTILLO ") -> CLIENTE JUAN CARLOS QUIROZ TORRES NETFLIX 4S VENDEDOR BENJAMIN SALAZAR SUPERVISOR JOSE IGNACIO QUEVEDO CASTILLO
A4: RSTV11Mn22 | B4: 45625 | C4: Calixta | D4: 33974955 | E4: 1199115815894 | F4: JUAN DAVID FERREIRA MENDEZ | G4: FRMNJN75082402H100 | H4: 6862344840 | I4: 1-199108582228 | J4: Universal+ Paramount+ Golden PROMOCION DE 1 MES | K4: ACTIVO | L4: UPSALE | M4: =CONCATENATE("CLIENTE ", F4," ",J4, "VENDEDOR BENJAMIN SALAZAR SUPERVISOR JOSE IGNACIO QUEVEDO CASTILLO ") -> CLIENTE JUAN DAVID FERREIRA MENDEZ Universal+ Paramount+ Golden PROMOCION DE 1 MES VENDEDOR BENJAMIN SALAZAR SUPERVISOR JOSE IGNACIO QUEVEDO CASTILLO
A5: RSTV11Mn23 | B5: 45625 | C5: Calixta | D5: 41366077 | E5: 1199115815858 | F5: VANIA FABIOLA ALVAREZ AGUILAR | G5: ALAGVN90103015M000 | H5: 7227753535 | I5: 1-199115813667 | J5: Universal+ Paramount+ Golden PROMOCION DE 1 MES | K5: ACTIVO | L5: UPSALE | M5: =CONCATENATE("CLIENTE ", F5," ",J5, "VENDEDOR BENJAMIN SALAZAR SUPERVISOR JOSE IGNACIO QUEVEDO CASTILLO ") -> CLIENTE VANIA FABIOLA ALVAREZ AGUILAR Universal+ Paramount+ Golden PROMOCION DE 1 MES VENDEDOR BENJAMIN SALAZAR SUPERVISOR JOSE IGNACIO QUEVEDO CASTILLO
A6: RSTV11Mn27 | B6: 45625 | C6: Llamada | D6: 42710526 | E6: 1199115139203 | F6: RUBEN ORTIZ REQUENA | G6: ORRQRB65081528H900 | H6: 8332514448 | I6: 1-199115138530 | J6: Universal+ Paramount+ Golden PROMOCION DE 1 MES | K6: ACTIVO | L6: UPSALE | M6: =CONCATENATE("CLIENTE ", F6," ",J6, "VENDEDOR BENJAMIN SALAZAR SUPERVISOR JOSE IGNACIO QUEVEDO CASTILLO ") -> CLIENTE RUBEN ORTIZ REQUENA Universal+ Paramount+ Golden PROMOCION DE 1 MES VENDEDOR BENJAMIN SALAZAR SUPERVISOR JOSE IGNACIO QUEVEDO CASTILLO
A7: RSTV11Mn29 | B7: 45625 | C7: Calixta | D7: 38796180 | E7: 1199126065432 | F7: CARLOS HERNANDEZ HERNANDEZ | G7: HRHRCR86071224H900 | H7: 3330068912 | I7: 1-199115816486 | J7: Universal+ Paramount+ Golden PROMOCION DE 1 MES | K7: ACTIVO | L7: UPSALE | M7: =CONCATENATE("CLIENTE ", F7," ",J7, "VENDEDOR BENJAMIN SALAZAR SUPERVISOR JOSE IGNACIO QUEVEDO CASTILLO ") -> CLIENTE CARLOS HERNANDEZ HERNANDEZ Universal+ Paramount+ Golden PROMOCION DE 1 MES VENDEDOR BENJAMIN SALAZAR SUPERVISOR JOSE IGNACIO QUEVEDO CASTILLO
A8: RSTV11Mn39 | B8: 45630 | C8: llamada | D8: 37388017 | E8: 1199531177142 | F8: NORIS ZURITA ACCENT | G8: NA | H8: 5578940639 | I8: 1-199523679438 | J8: Universal+ Paramount+ Golden PROMOCION DE 1 MES | K8: ACTIVO | L8: UPSALE | M8: =CONCATENATE("CLIENTE ", F8," ",J8, "VENDEDOR BENJAMIN SALAZAR SUPERVISOR JOSE IGNACIO QUEVEDO CASTILLO ") -> CLIENTE NORIS ZURITA ACCENT Universal+ Paramount+ Golden PROMOCION DE 1 MES VENDEDOR BENJAMIN SALAZAR SUPERVISOR JOSE IGNACIO QUEVEDO CASTILLO
A9: RSTV11Mn42 | B9: 45631 | C9: Calixta | D9: 19179379 | E9: 1199591122122 | F9: JAVIER BARRERA | G9: XXBRHG73110609H800 | H9: 5627472735 | I9: 1-199587782596 | J9: Universal+ Paramount+ Golden PROMOCION DE 1 MES | K9: ACTIVO | L9: UPSALE | M9: =CONCATENATE("CLIENTE ", F9," ",J9, "VENDEDOR BENJAMIN SALAZAR SUPERVISOR JOSE IGNACIO QUEVEDO CASTILLO ") -> CLIENTE JAVIER BARRERA Universal+ Paramount+ Golden PROMOCION DE 1 MES VENDEDOR BENJAMIN SALAZAR SUPERVISOR JOSE IGNACIO QUEVEDO CASTILLO
A10: RSTV11Mn43 | B10: 45631 | C10: llamada | D10: 43171233 | E10: 1199598995512 | F10: NORMA ALICIA AVENA VILLELA seguimiento movil | G10: AVVLNR69011825M700 | H10: #6645044435 | I10: 1-199607285063 | J10: Universal+ Paramount+ Golden PROMOCION DE 1 MES | K10: ACTIVO | L10: UPSALE | M10: =CONCATENATE("CLIENTE ", F10," ",J10, "VENDEDOR BENJAMIN SALAZAR SUPERVISOR JOSE IGNACIO QUEVEDO CASTILLO ") -> CLIENTE NORMA ALICIA AVENA VILLELA seguimiento movil Universal+ Paramount+ Golden PROMOCION DE 1 MES VENDEDOR BENJAMIN SALAZAR SUPERVISOR JOSE IGNACIO QUEVEDO CASTILLO
A11: RSTV11Mn45 | B11: 45632 | C11: llamada | D11: 37070315 | E11: 1199661442922 | F11: NORMA ALEJANDRA GODOY GOMEZ | G11: GDGMNR77062409M200 | H11: 5539513645 | I11: 1-199667402948 | J11: Universal+ Paramount+ Golden PROMOCION DE 1 MES | K11: ACTIVO | L11: UPSALE | M11: =CONCATENATE("CLIENTE ", F11," ",J11, "VENDEDOR BENJAMIN SALAZAR SUPERVISOR JOSE IGNACIO QUEVEDO CASTILLO ") -> CLIENTE NORMA ALEJANDRA GODOY GOMEZ Universal+ Paramount+ Golden PROMOCION DE 1 MES VENDEDOR BENJAMIN SALAZAR SUPERVISOR JOSE IGNACIO QUEVEDO CASTILLO
A12: RSTV11Mn46 | B12: 45632 | C12: llamada | D12: 34304879 | E12: 1199667404476 | F12: BERENICE FUENTES MONTAÑO | G12: FNMNBR01121217M200 | H12: 7351860957 | I12: 1-199661442975 | J12: Universal+ Paramount+ Golden PROMOCION DE 1 MES | K12: ACTIVO | L12: UPSALE | M12: =CONCATENATE("CLIENTE ", F12," ",J12, "VENDEDOR BENJAMIN SALAZAR SUPERVISOR JOSE IGNACIO QUEVEDO CASTILLO ") -> CLIENTE BERENICE FUENTES MONTAÑO Universal+ Paramount+ Golden PROMOCION DE 1 MES VENDEDOR BENJAMIN SALAZAR SUPERVISOR JOSE IGNACIO QUEVEDO CASTILLO
A13: RSTV11Mn47 | B13: 45632 | C13: llamada | D13: 24362832 | E13: 1199688190325 | F13: JORGE ALBERTO GAYTAN VAZQUEZ | G13: NA | H13: 5617035051 | I13: 1-199688189469 | J13: Universal+ Paramount+ Golden PROMOCION DE 1 MES | K13: ACTIVO | L13: UPSALE | M13: =CONCATENATE("CLIENTE ", F13," ",J13, "VENDEDOR BENJAMIN SALAZAR SUPERVISOR JOSE IGNACIO QUEVEDO CASTILLO ") -> CLIENTE JORGE ALBERTO GAYTAN VAZQUEZ Universal+ Paramount+ Golden PROMOCION DE 1 MES VENDEDOR BENJAMIN SALAZAR SUPERVISOR JOSE IGNACIO QUEVEDO CASTILLO
A14: RSTV11Mn49 | B14: 45632 | C14: Calixta | D14: 37743747 | E14: 1199686862132 | F14: ALEJANDRA SARAHI TAPIA ESPINOSA | G14: TPESAL93070219M600 | H14: 8129450591 | I14: 1-199688191372 | J14: Universal+ Paramount+ Golden PROMOCION DE 1 MES | K14: ACTIVO | L14: UPSALE | M14: =CONCATENATE("CLIENTE ", F14," ",J14, "VENDEDOR BENJAMIN SALAZAR SUPERVISOR JOSE IGNACIO QUEVEDO CASTILLO ") -> CLIENTE ALEJANDRA SARAHI TAPIA ESPINOSA Universal+ Paramount+ Golden PROMOCION DE 1 MES VENDEDOR BENJAMIN SALAZAR SUPERVISOR JOSE IGNACIO QUEVEDO CASTILLO
A15: RSTV11Mn50 | B15: 45632 | C15: Llamada | D15: 17277617 | E15: 1199711356606 | F15: OSWALDO MENDOZA RODRIGUEZ | G15: NA | H15: 5545218967 | I15: 1-199705130606 | J15: Universal+ Paramount+ Golden PROMOCION DE 1 MES | K15: ACTIVO | L15: UPSALE | M15: =CONCATENATE("CLIENTE ", F15," ",J15, "VENDEDOR BENJAMIN SALAZAR SUPERVISOR JOSE IGNACIO QUEVEDO CASTILLO ") -> CLIENTE OSWALDO MENDOZA RODRIGUEZ Universal+ Paramount+ Golden PROMOCION DE 1 MES VENDEDOR BENJAMIN SALAZAR SUPERVISOR JOSE IGNACIO QUEVEDO CASTILLO
A16: RSTV11Mn51 | B16: 45632 | C16: Llamada | D16: 25272117 | E16: 1199714496603 | F16: DELIA EVELIA RANGEL ESPINOSA | G16: NA | H16: 5619198424 | I16: 1-199703870334 | J16: Universal+ Paramount+ Golden PROMOCION DE 1 MES | K16: ACTIVO | L16: UPSALE | M16: =CONCATENATE("CLIENTE ", F16," ",J16, "VENDEDOR BENJAMIN SALAZAR SUPERVISOR JOSE IGNACIO QUEVEDO CASTILLO ") -> CLIENTE DELIA EVELIA RANGEL ESPINOSA Universal+ Paramount+ Golden PROMOCION DE 1 MES VENDEDOR BENJAMIN SALAZAR SUPERVISOR JOSE IGNACIO QUEVEDO CASTILLO
A17: RSTV11Mn54 | B17: 45633 | C17: Llamada | D17: 36410582 | E17: 1199783997392 | F17: EMANUEL LOBATO RUIZ | G17: NA | H17: 5625868953 | I17: 1-199767113608 | J17: Universal+ Paramount+ Golden PROMOCION DE 1 MES | K17: ACTIVO | L17: UPSALE | M17: =CONCATENATE("CLIENTE ", F17," ",J17, "VENDEDOR BENJAMIN SALAZAR SUPERVISOR JOSE IGNACIO QUEVEDO CASTILLO ") -> CLIENTE EMANUEL LOBATO RUIZ Universal+ Paramount+ Golden PROMOCION DE 1 MES VENDEDOR BENJAMIN SALAZAR SUPERVISOR JOSE IGNACIO QUEVEDO CASTILLO
A18: RSTV11Mn56 | B18: 45634 | C18: Calixta | D18: 34092658 | E18: 1199813472723 | F18: ADELINA GOMEZ BAUTISTA | G18: GMBTAD69010509M500 | H18: 5636054228 | I18: 1-199779027813 | J18: Universal+ Paramount+ Golden PROMO DE 1 MES | K18: ACTIVO | L18: UPSALE | M18: =CONCATENATE("CLIENTE ", F18," ",J18, "VENDEDOR BENJAMIN SALAZAR SUPERVISOR JOSE IGNACIO QUEVEDO CASTILLO ") -> CLIENTE ADELINA GOMEZ BAUTISTA Universal+ Paramount+ Golden PROMO DE 1 MES VENDEDOR BENJAMIN SALAZAR SUPERVISOR JOSE IGNACIO QUEVEDO CASTILLO
A19: RSTV11Mn58 | B19: 45634 | C19: Llamada | D19: 35342082 | E19: 1199816199272 | F19: FERNANDO JONATHAN GERONIMO BERCHELT | G19: GRBRFR85042631H600 | H19: 9984766482 | I19: 1-199845949004 | J19: Universal+ Paramount+ Golden PROMO DE 1 MES | K19: ACTIVO | L19: UPSALE | M19: =CONCATENATE("CLIENTE ", F19," ",J19, "VENDEDOR BENJAMIN SALAZAR SUPERVISOR JOSE IGNACIO QUEVEDO CASTILLO ") -> CLIENTE FERNANDO JONATHAN GERONIMO BERCHELT Universal+ Paramount+ Golden PROMO DE 1 MES VENDEDOR BENJAMIN SALAZAR SUPERVISOR JOSE IGNACIO QUEVEDO CASTILLO
A20: RSTV11Mn59 | B20: 45635 | C20: Llamada | D20: 25299321 | E20: 1199908149167 | F20: JOSE LUIS PUENTE MEDINA | G20: NA | H20: 8120409244 | I20: 1-199910633009 | J20: Universal+ Paramount+ Golden PROMO DE 1 MES | K20: ACTIVO | L20: UPSALE | M20: =CONCATENATE("CLIENTE ", F20," ",J20, " VENDEDOR BENJAMIN SALAZAR SUPERVISOR JOSE IGNACIO QUEVEDO CASTILLO ") -> CLIENTE JOSE LUIS PUENTE MEDINA Universal+ Paramount+ Golden PROMO DE 1 MES VENDEDOR BENJAMIN SALAZAR SUPERVISOR JOSE IGNACIO QUEVEDO CASTILLO
A21: RSTV11Mn60 | B21: 45635 | C21: Llamada | D21: 34317365 | E21: 1199903613382 | F21: DANIEL ALANIS SALAZAR | G21: NA | H21: / | I21: 1-199908149200 | J21: Universal+ Paramount+ Golden PROMO DE 1 MES | K21: ACTIVO | L21: UPSALE | M21: =CONCATENATE("CLIENTE ", F21," ",J21, " VENDEDOR BENJAMIN SALAZAR SUPERVISOR JOSE IGNACIO QUEVEDO CASTILLO ") -> CLIENTE DANIEL ALANIS SALAZAR Universal+ Paramount+ Golden PROMO DE 1 MES VENDEDOR BENJAMIN SALAZAR SUPERVISOR JOSE IGNACIO QUEVEDO CASTILLO
A22: RSTV11Mn62 | B22: 45635 | C22: Llamada | D22: 37920953 | E22: 1199927380672 | F22: MAGDA SAGRARIO HERNANDEZ ALMANZA | G22: NA | H22: / | I22: 1-199912903582 | J22: Universal+ Paramount+ Golden PROMO DE 1 MES | K22: PRE-ACT | L22: UPSALE | M22: =CONCATENATE("CLIENTE ", F22," ",J22, " VENDEDOR BENJAMIN SALAZAR SUPERVISOR JOSE IGNACIO QUEVEDO CASTILLO ") -> CLIENTE MAGDA SAGRARIO HERNANDEZ ALMANZA Universal+ Paramount+ Golden PROMO DE 1 MES VENDEDOR BENJAMIN SALAZAR SUPERVISOR JOSE IGNACIO QUEVEDO CASTILLO
A23: RSTV11Mn63 | B23: 45635 | C23: Llamada | D23: 37242856 | E23: 1199917560382 | F23: GUADALUPE ROBLEDO PEREZ | G23: RBPRGD63121219H600 | H23: / | I23: 1-199927380695 | J23: Universal+ Paramount+ Golden PROMO DE 1 MES | K23: PRE-ACT | L23: UPSALE | M23: =CONCATENATE("CLIENTE ", F23," ",J23, " VENDEDOR BENJAMIN SALAZAR SUPERVISOR JOSE IGNACIO QUEVEDO CASTILLO ") -> CLIENTE GUADALUPE ROBLEDO PEREZ Universal+ Paramount+ Golden PROMO DE 1 MES VENDEDOR BENJAMIN SALAZAR SUPERVISOR JOSE IGNACIO QUEVEDO CASTILLO
A24: RSTV11Mn64 | B24: 45635 | C24: Llamada | D24: 34851497 | E24: 1199907935248 | F24: ADRIAN PADILLA NAVA | G24: PDNVAD85120719H600 | H24: / | I24: 1-199907934388 | J24: Universal+ Golden PROMO DE 1 MES | K24: ACTIVO | L24: UPSALE | M24: =CONCATENATE("CLIENTE ", F24," ",J24, " VENDEDOR BENJAMIN SALAZAR SUPERVISOR JOSE IGNACIO QUEVEDO CASTILLO ") -> CLIENTE ADRIAN PADILLA NAVA Universal+ Golden PROMO DE 1 MES VENDEDOR BENJAMIN SALAZAR SUPERVISOR JOSE IGNACIO QUEVEDO CASTILLO
A25: RSTV11Mn65 | B25: 45635 | C25: Llamada | D25: 19723385 | E25: 1199946746915 | F25: JOSE LUIS GARCIA GALLEGO | G25: GRGLLS73111002H001 | H25: 6641233546 | I25: 1-199946745539 | J25: Universal+ Paramount+ Golden PROMO DE 1 MES | K25: ACTIVO | L25: UPSALE | M25: =CONCATENATE("CLIENTE ", F25," ",J25, " VENDEDOR BENJAMIN SALAZAR SUPERVISOR JOSE IGNACIO QUEVEDO CASTILLO ") -> CLIENTE JOSE LUIS GARCIA GALLEGO Universal+ Paramount+ Golden PROMO DE 1 MES VENDEDOR BENJAMIN SALAZAR SUPERVISOR JOSE IGNACIO QUEVEDO CASTILLO
A26: RSTV11Mn67 | B26: 45636 | C26: Calixta | D26: 38684931 | E26: 1200027654448 | F26: ULISES SANTOS GALINDO | G26: SNGLUL86012709H200 | H26: 5519702234 | I26: 1-200027653825 | J26: Universal+ Paramount+ Golden PROMO DE 1 MES | K26: ACTIVO | L26: UPSALE | M26: =CONCATENATE("CLIENTE ", F26," ",J26, " VENDEDOR BENJAMIN SALAZAR SUPERVISOR JOSE IGNACIO QUEVEDO CASTILLO ") -> CLIENTE ULISES SANTOS GALINDO Universal+ Paramount+ Golden PROMO DE 1 MES VENDEDOR BENJAMIN SALAZAR SUPERVISOR JOSE IGNACIO QUEVEDO CASTILLO
A27: RSTV11Mn68 | B27: 45636 | C27: Llamada | D27: 24722819 | E27: 1200038550270 | F27: LAURA RAMIREZ MARTINEZ | G27: RMMRLR86042509M000 | H27: 55630958388 | I27: 1-200038549809 | J27: Golden PROMO DE 1 MES | K27: ACTIVO | L27: UPSALE | M27: =CONCATENATE("CLIENTE ", F27," ",J27, " VENDEDOR BENJAMIN SALAZAR SUPERVISOR JOSE IGNACIO QUEVEDO CASTILLO ") -> CLIENTE LAURA RAMIREZ MARTINEZ Golden PROMO DE 1 MES VENDEDOR BENJAMIN SALAZAR SUPERVISOR JOSE IGNACIO QUEVEDO CASTILLO
A28: RSTV11Mn69 | B28: 45636 | C28: Llamada | D28: 26824098 | E28: 1200107316768 | F28: ROSA CARRETERO SANTIAGO | G28: CRSNRS74083002M600 | H28: 5511395574 | I28: 1-200038551433 | J28: Universal+ Paramount+ Golden PROMO DE 1 MES | K28: ACTIVO | L28: UPSALE | M28: =CONCATENATE("CLIENTE ", F28," ",J28, " VENDEDOR BENJAMIN SALAZAR SUPERVISOR JOSE IGNACIO QUEVEDO CASTILLO ") -> CLIENTE ROSA CARRETERO SANTIAGO Universal+ Paramount+ Golden PROMO DE 1 MES VENDEDOR BENJAMIN SALAZAR SUPERVISOR JOSE IGNACIO QUEVEDO CASTILLO
A29: RSTV11Mn70 | B29: 45636 | C29: Llamada | D29: 43645487 | E29: 1200040196362 | F29: TERESITA FLORES EQUIZA | G29: FLEQTR51022809M700 | H29: 5628165905 | I29: 1-200040195325 | J29: Universal+ Paramount+ Golden PROMO DE 1 MES | K29: ACTIVO | L29: UPSALE | M29: =CONCATENATE("CLIENTE ", F29," ",J29, " VENDEDOR BENJAMIN SALAZAR SUPERVISOR JOSE IGNACIO QUEVEDO CASTILLO ") -> CLIENTE TERESITA FLORES EQUIZA Universal+ Paramount+ Golden PROMO DE 1 MES VENDEDOR BENJAMIN SALAZAR SUPERVISOR JOSE IGNACIO QUEVEDO CASTILLO
A30: RSTV11Mn77 | B30: 45638 | C30: Llamada | D30: 42863195 | E30: 1200276198087 | F30: ESPERANZA GARCIA MORA | G30: GRMRES00021214M800 | H30: 3931793366 | I30: 1-200276197561 | J30: Paramount+ PROMO DE 1 MES | K30: ACTIVO | L30: UPSALE | M30: =CONCATENATE("CLIENTE ", F30," ",J30, " VENDEDOR BENJAMIN SALAZAR SUPERVISOR JOSE IGNACIO QUEVEDO CASTILLO ") -> CLIENTE ESPERANZA GARCIA MORA Paramount+ PROMO DE 1 MES VENDEDOR BENJAMIN SALAZAR SUPERVISOR JOSE IGNACIO QUEVEDO CASTILLO
A31: RSTV11Mn80 | B31: 45640 | C31: Llamada | D31: 17853923 | E31: 1200441438609 | F31: MARIA TERESA MARTINEZ MATA | G31: MRMTTR61020424M900 | H31: 5567330747 | I31: 1-200461921964 | J31: Universal+ Paramount+ Golden PROMO DE 1 MES | K31: ACTIVO | L31: UPSALE | M31: =CONCATENATE("CLIENTE ", F31," ",J31, " VENDEDOR BENJAMIN SALAZAR SUPERVISOR JOSE IGNACIO QUEVEDO CASTILLO ") -> CLIENTE MARIA TERESA MARTINEZ MATA Universal+ Paramount+ Golden PROMO DE 1 MES VENDEDOR BENJAMIN SALAZAR SUPERVISOR JOSE IGNACIO QUEVEDO CASTILLO
A32: RSTV11Mn85 | B32: 45640 | C32: Llamada | D32: 36604029 | E32: 1200506805558 | F32: ALBERTO AVALOS LEYVA | G32: 11571303 cedula | H32: 5587771097 | I32: 1-200506804756 | J32: Universal+ Paramount+ Golden PROMO DE 1 MES | K32: ACTIVO | L32: UPSALE | M32: =CONCATENATE("CLIENTE ", F32," ",J32, " VENDEDOR BENJAMIN SALAZAR SUPERVISOR JOSE IGNACIO QUEVEDO CASTILLO ") -> CLIENTE ALBERTO AVALOS LEYVA Universal+ Paramount+ Golden PROMO DE 1 MES VENDEDOR BENJAMIN SALAZAR SUPERVISOR JOSE IGNACIO QUEVEDO CASTILLO
A33: RSTV11Mn86 | C33: Llamada | G33: SNALAB970808H700 | K33: PRE-ACT | M33: =CONCATENATE("CLIENTE ", F33," ",J33, " VENDEDOR BENJAMIN SALAZAR SUPERVISOR JOSE IGNACIO QUEVEDO CASTILLO ") -> CLIENTE VENDEDOR BENJAMIN SALAZAR SUPERVISOR JOSE IGNACIO QUEVEDO CASTILLO
A34: RSTV11Mn87 | C34: Llamada | K34: PRE-ACT | M34: =CONCATENATE("CLIENTE ", F34," ",J34, " VENDEDOR BENJAMIN SALAZAR SUPERVISOR JOSE IGNACIO QUEVEDO CASTILLO ") -> CLIENTE VENDEDOR BENJAMIN SALAZAR SUPERVISOR JOSE IGNACIO QUEVEDO CASTILLO
A35: RSTV11Mn88 | C35: Llamada | K35: PRE-ACT | M35: =CONCATENATE("CLIENTE ", F35," ",J35, " VENDEDOR BENJAMIN SALAZAR SUPERVISOR JOSE IGNACIO QUEVEDO CASTILLO ") -> CLIENTE VENDEDOR BENJAMIN SALAZAR SUPERVISOR JOSE IGNACIO QUEVEDO CASTILLO
A36: RSTV11Mn89 | C36: Llamada | K36: PRE-ACT | M36: =CONCATENATE("CLIENTE ", F36," ",J36, " VENDEDOR BENJAMIN SALAZAR SUPERVISOR JOSE IGNACIO QUEVEDO CASTILLO ") -> CLIENTE VENDEDOR BENJAMIN SALAZAR SUPERVISOR JOSE IGNACIO QUEVEDO CASTILLO
A37: RSTV11Mn90 | C37: Llamada | K37: PRE-ACT | M37: =CONCATENATE("CLIENTE ", F37," ",J37, " VENDEDOR BENJAMIN SALAZAR SUPERVISOR JOSE IGNACIO QUEVEDO CASTILLO ") -> CLIENTE VENDEDOR BENJAMIN SALAZAR SUPERVISOR JOSE IGNACIO QUEVEDO CASTILLO
A38: RSTV11Mn91 | C38: Llamada | K38: PRE-ACT | M38: =CONCATENATE("CLIENTE ", F38," ",J38, " VENDEDOR BENJAMIN SALAZAR SUPERVISOR JOSE IGNACIO QUEVEDO CASTILLO ") -> CLIENTE VENDEDOR BENJAMIN SALAZAR SUPERVISOR JOSE IGNACIO QUEVEDO CASTILLO
A39: RSTV11Mn92 | C39: Llamada | K39: PRE-ACT | M39: =CONCATENATE("CLIENTE ", F39," ",J39, " VENDEDOR BENJAMIN SALAZAR SUPERVISOR JOSE IGNACIO QUEVEDO CASTILLO ") -> CLIENTE VENDEDOR BENJAMIN SALAZAR SUPERVISOR JOSE IGNACIO QUEVEDO CASTILLO
A40: RSTV11Mn93 | C40: Llamada | K40: PRE-ACT | M40: =CONCATENATE("CLIENTE ", F40," ",J40, " VENDEDOR BENJAMIN SALAZAR SUPERVISOR JOSE IGNACIO QUEVEDO CASTILLO ") -> CLIENTE VENDEDOR BENJAMIN SALAZAR SUPERVISOR JOSE IGNACIO QUEVEDO CASTILLO
...

Sheet Estadistica 
A1: Sistema de Registros de Televentas - SIRT | L1: version 2.0
J2: =TODAY() -> 45641
F8: MOVIL 5 | G8: MOVIL 8 12M | H8: MOVIL 8 | I8: MOVIL 15 | J8: MOVIL C 12M | K8: MOVIL C | M8: UP
B9: Cancelados | D9: =COUNTIF(Movil!K2:'Movil'!K3006, "CAN") -> 5 | F9: =COUNTIF(Movil!J2:'Movil'!J3007, "IZZI MOVIL 5 12M") -> 11 | G9: =COUNTIF(Movil!J2:'Movil'!J3007, "IZZI MOVIL 8 12M") -> 12 | H9: =COUNTIF(Movil!J2:'Movil'!J3007, "IZZI MOVIL 8") -> 3 | I9: =COUNTIF(Movil!J2:'Movil'!J3007, "IZZI MOVIL 15") -> 1 | J9: =COUNTIF(Movil!J2:'Movil'!J3007, "IZZI movil comparte tus datos 12M PROMO 3M") -> 28 | K9: =COUNTIF(Movil!J2:'Movil'!L3007, "350") -> 0 | M9: =COUNTIF(UPs!L2:'UPs'!L2983, "UPSALE") -> 31
B10: Pre Activación | D10: =COUNTIF(Movil!K2:'Movil'!K3007, "PRE-ACT") -> 51
B11: Activos | D11: =COUNTIF(Movil!K2:'Movil'!K3007, "ACTIVO") -> 11
B12: Tasa de activación | D12: =(100/F21*D11)/100 -> 0.1641791
F18: ALCANCE
F19: CALI | G19: CALL
B20: HOY | C20: =COUNTIF(Movil!#REF!:'Movil'!B3007, "14/12/2024") -> #REF! | D20: ventas | F20: =COUNTIF(Movil!C2:'Movil'!C3007,"Calixta ") -> 23 | G20: =COUNTIF(Movil!C2:'Movil'!C3007, "Llamada") -> 44
F21: =F20+G20 -> 67
B28: Ventas diarias
B29: =CONCATENATE("Cuenta: ", Movil!D49, " Orden: ", Movil!I49) -> Cuenta: 19086094 Orden: 1-200256851391
B30: =CONCATENATE("Cuenta: ", Movil!D50, " Orden: ", Movil!I50) -> Cuenta: 43708593 Orden: 1-200256850405 | E30: Pendiente validar
B31: =CONCATENATE("Cuenta: ", Movil!#REF!, " Orden: ", Movil!#REF!) -> #REF!
B32: =CONCATENATE("Cuenta: ", Movil!D51, " Orden: ", Movil!I51) -> Cuenta: 37569014 Orden: 1-200357366127
B33: =CONCATENATE("Cuenta: ", Movil!D52, " Orden: ", Movil!I52) -> Cuenta: 42533249 Orden: 1-200357367297
B34: =CONCATENATE("Cuenta: ", Movil!#REF!, " Orden: ", Movil!I53) -> #REF!
B35: =CONCATENATE("Cuenta: ", Movil!D53, " Orden: ", Movil!#REF!) -> #REF!
B36: =CONCATENATE("Cuenta: ", Movil!D54, " Orden: ", Movil!I54) -> Cuenta: 39415438 Orden: 1-200441440033
B37: =CONCATENATE("Cuenta: ", Movil!D55, " Orden: ", Movil!I55) -> Cuenta: 31688382 Orden: 1-200461923566
B38: =CONCATENATE("Cuenta: ", Movil!D56, " Orden: ", Movil!I56) -> Cuenta: 31688382 Orden: 1-200461923566
B39: =CONCATENATE("Cuenta: ", Movil!#REF!, " Orden: ", Movil!#REF!) -> #REF!
B40: =CONCATENATE("Cuenta: ", Movil!D57, " Orden: ", Movil!I57) -> Cuenta: Orden:
B41: =CONCATENATE("Cuenta: ", Movil!D58, " Orden: ", Movil!I58) -> Cuenta: Orden:

Sheet Prospectos 
A1: Sistema de Registros de Televentas - SIRT | G1: version 2.0
E2: =TODAY() -> 45641
B3: MEDIO | C3: CONTACTO | D3: CUENTA | F3: DETALLE | G3: ULT CONTACTO
A4: 45643 | B4: llamada | C4: 5588048018 | F4: netflix y 3 canales promo
A5: 45646 | B5: llamada | C5: 3312516939 | D5: 39953342 | F5: IZZI ,MOVIL 8 12M
A6: 45644 | B6: llamada | C6: 5591189211 | D6: 34736434 | F6: izzi movil 5 | I6: PERDIDO
A7: 45658 | C7: 8119909756 | D7: 25329723 | I7: RIESGO
B8: llamada | C8: 8121769060 | D8: 22051398 | E8: REYNA ISABEL GARCIA GARCIA | F8: viernes 4:00 pm movil | G8: 45640 | I8: CONTACTADO
B9: llamada | C9: 8147723957 | D9: 37363061 | E9: ADRIANA NOHEMI ESPINOZA FUENTES | F9: 3 líneas movil | G9: 45640 | I9: PENDIENTE
B10: llamada | C10: 5566684469 | D10: 32090021 | E10: FERNANDO DURAN SALDAÑA | F10: ambas 12:00 tij | G10: 45640
A11: 45644 | B11: llamada | C11: 5580493436 | D11: 38069382 | E11: LISSET ERNESTINA MUÑOZ CORONA | F11: movil, netflix
B12: llamada | C12: 5531264339 | D12: 25311633 | E12: ROMAN DANIEL CRESPO GARCIA | F12: outbound | G12: 45640
B13: llamada | C13: 5549447175 | D13: 24935201 | E13: ALFREDO BENAVIDES MEJIA | F13: 2:00 horaTIJ movil | G13: 45640
B14: llamada | C14: 5539482050 | D14: 27382053 | E14: BRAYAN GUSTAVO CAMARENA CALZADA | F14: movil 1:00pm horaTIJ | G14: 45640
B15: llamada | C15: 2722600189 | D15: 23967148 | F15: LINEAS DE MOVIL RECUPERA | G15: 45640
B16: llamada | C16: 5574140409 | D16: 18995901 | E16: SILVIA MARISSA SALAZAR CRUZ | F16: LINEA DE MOVIL 5 RECUPERA 9:30 tij | G16: 45640
A17: 45648 | B17: llamada | C17: 5571764215 | D17: 23940592 | E17: FEDERICO PEREZ ALBORES | F17: LINEA DE MOVIL 5 RECUPERA
A18: 45646 | C18: 9811379081 | D18: 34890255 | E18: ANA ROSA COLLI BASTO | F18: PROSPECTO 20/DIC | G18: 45640
A19: 45659 | C19: #6645044435 | D19: 43171233 | E19: NORMA ALICIA AVENA VILLELA | F19: MOVIL
A20: 45640 | C20: 9984752056 | D20: 36484245 | E20: JOSE SANTOS ISAIAS SULUB FLORES | F20: 1:50 Htij | G20: 45640
B21: llamada | C21: 8120084881 | D21: 38038358 | E21: ALFREDO RIVERA RAMON | F21: movil 2:00 Hmonterrey | G21: 45640
B22: llamada | C22: 5565765570 | D22: 22389155 | E22: JESSICA CERVANTES PERETE | F22: movil 12:40Htij | G22: 45640
B23: llamada | C23: 3335985100 | D23: 39845757 | E23: MIGUEL ANGEL CHAVOYA TAMAYO | F23: TLAQUEPAQUE MOVIL COMPARTE 2:00 PM hTIJ

Sheet Hoja1
A1: Cuenta | B1: Telefono | C1: Marcación | D1: Resultado
A2: 20231565 | C2: =CONCATENATE("#",B2) -> #
A3: 33151124 | C3: =CONCATENATE("#",B3) -> #
A4: 33620375 | C4: =CONCATENATE("#",B4) -> #
A5: 32651531 | B5: 7717220860 | C5: =CONCATENATE("#",B5) -> #7717220860
A6: 29649365 | B6: 5620976639 | C6: =CONCATENATE("#",B6) -> #5620976639
A7: 27846060 | B7: 5517613233 | C7: =CONCATENATE("#",B7) -> #5517613233
A8: 38346423 | B8: 7352159359 | C8: =CONCATENATE("#",B8) -> #7352159359
A9: 50721917 | B9: 6611130822 | C9: =CONCATENATE("#",B9) -> #6611130822
A10: 36692020 | B10: 5531521534 | C10: =CONCATENATE("#",B10) -> #5531521534
A11: 36994743 | B11: 5574323079 | C11: =CONCATENATE("#",B11) -> #5574323079
A12: 36533961 | B12: 5549427785 | C12: =CONCATENATE("#",B12) -> #5549427785
A13: 35434836 | B13: 8126268915 | C13: =CONCATENATE("#",B13) -> #8126268915
A14: 33726275 | B14: 8115303949 | C14: =CONCATENATE("#",B14) -> #8115303949
A15: 31597918 | B15: 6643719924 | C15: =CONCATENATE("#",B15) -> #6643719924
A16: 36648568 | C16: =CONCATENATE("#",B16) -> #
A17: 35258989 | C17: =CONCATENATE("#",B17) -> #
A18: 50571578 | C18: =CONCATENATE("#",B18) -> #
A19: 55257232 | C19: =CONCATENATE("#",B19) -> #
A20: 39018307 | C20: =CONCATENATE("#",B20) -> #
A21: 31724628 | C21: =CONCATENATE("#",B21) -> #
A22: 31351792 | C22: =CONCATENATE("#",B22) -> #
A23: 39919099 | C23: =CONCATENATE("#",B23) -> #
A24: 30388220 | C24: =CONCATENATE("#",B24) -> #
A25: 37093914 | C25: =CONCATENATE("#",B25) -> #
A26: 35511047 | C26: =CONCATENATE("#",B26) -> #
A27: 37213076 | C27: =CONCATENATE("#",B27) -> #
... A32: 34781470 | C32: =CONCATENATE("#",B32) -> #
C33: =CONCATENATE("#",B33) -> #
A34: 38892268 | C34: =CONCATENATE("#",B34) -> #
A35: 50814347 | C35: =CONCATENATE("#",B35) -> #
A36: 36965736 | C36: =CONCATENATE("#",B36) -> #
A37: 36965736 | C37: =CONCATENATE("#",B37) -> #
A38: 16818881 | C38: =CONCATENATE("#",B38) -> #
A39: 40011934 | C39: =CONCATENATE("#",B39) -> #
A40: 37002125 | C40: =CONCATENATE("#",B40) -> #
A41: 37002125 | C41: =CONCATENATE("#",B41) -> #
A42: 25559768 | C42: =CONCATENATE("#",B42) -> #
A43: 25559768 | C43: =CONCATENATE("#",B43) -> #
A44: 23147315 | C44: =CONCATENATE("#",B44) -> #
...
